<mujoco model="xhand_left">
  <compiler angle="radian" meshdir="./meshes/"/>

  <asset>
    <mesh name="left_hand_link" file="left_hand_link.STL"/>
    <mesh name="left_hand_ee_link" file="left_hand_ee_link.STL"/>
    <mesh name="left_hand_thumb_bend_link" file="left_hand_thumb_bend_link.STL"/>
    <mesh name="left_hand_thumb_rota_link1" file="left_hand_thumb_rota_link1.STL"/>
    <mesh name="left_hand_thumb_rota_link2" file="left_hand_thumb_rota_link2.STL"/>
    <mesh name="left_hand_thumb_rota_tip" file="left_hand_thumb_rota_tip.STL"/>
    <mesh name="left_hand_index_bend_link" file="left_hand_index_bend_link.STL"/>
    <mesh name="left_hand_index_rota_link1" file="left_hand_index_rota_link1.STL"/>
    <mesh name="left_hand_index_rota_link2" file="left_hand_index_rota_link2.STL"/>
    <mesh name="left_hand_index_rota_tip" file="left_hand_index_rota_tip.STL"/>
    <mesh name="left_hand_mid_link1" file="left_hand_mid_link1.STL"/>
    <mesh name="left_hand_mid_link2" file="left_hand_mid_link2.STL"/>
    <mesh name="left_hand_mid_tip" file="left_hand_mid_tip.STL"/>
    <mesh name="left_hand_ring_link1" file="left_hand_ring_link1.STL"/>
    <mesh name="left_hand_ring_link2" file="left_hand_ring_link2.STL"/>
    <mesh name="left_hand_ring_tip" file="left_hand_ring_tip.STL"/>
    <mesh name="left_hand_pinky_link1" file="left_hand_pinky_link1.STL"/>
    <mesh name="left_hand_pinky_link2" file="left_hand_pinky_link2.STL"/>
    <mesh name="left_hand_pinky_tip" file="left_hand_pinky_tip.STL"/>
  </asset>

  <worldbody>
    <geom type="mesh" contype="0" conaffinity="0" group="1" density="0" rgba="0.866667 0.866667 0.890196 1" mesh="left_hand_link"/>
    <!-- <geom type="mesh" rgba="0.866667 0.866667 0.890196 1" mesh="left_hand_link"/> -->
    <geom pos="0 0 -0.065" quat="1 0 0 0" type="mesh" contype="0" conaffinity="0" group="1" density="0" rgba="0.698039 0.698039 0.698039 1" mesh="left_hand_ee_link"/>
    <!-- <geom pos="0 0 -0.065" quat="1 0 0 0" type="mesh" rgba="0.698039 0.698039 0.698039 1" mesh="left_hand_ee_link"/> -->
    <body name="left_hand_thumb_bend_link" pos="0.0228 -0.0095 -0.0305">
      <inertial pos="0.0145291 0.000901344 -0.000127912" quat="-0.028902 0.68936 -0.0167067 0.72365" mass="0.00985534" diaginertia="1.30648e-06 1.29142e-06 5.40957e-07"/>
      <joint name="left_hand_thumb_bend_joint" pos="0 0 0" axis="0 0 -1" range="0 1.83" actuatorfrcrange="-1.1 1.1" damping="1" frictionloss="1"/>
      <geom type="mesh" contype="0" conaffinity="0" group="1" density="0" rgba="0.890196 0.890196 0.913725 1" mesh="left_hand_thumb_bend_link"/>
      <!-- <geom type="mesh" rgba="0.890196 0.890196 0.913725 1" mesh="left_hand_thumb_bend_link"/> -->
      <body name="left_hand_thumb_rota_link1" pos="0.028599 -0.0083177 0.00178" quat="0.99124 -0.130499 0.00265603 -0.0201745">
        <inertial pos="0.0279279 0.000121046 -0.000277543" quat="0.0994744 0.703642 -0.0845458 0.698459" mass="0.153197" diaginertia="5.62164e-05 4.89587e-05 2.23807e-05"/>
        <joint name="left_hand_thumb_rota_joint1" pos="0 0 0" axis="0 1 0" range="-1.05 1.57" actuatorfrcrange="-1.1 1.1" damping="1" frictionloss="1"/>
        <geom type="mesh" contype="0" conaffinity="0" group="1" density="0" rgba="1 1 1 1" mesh="left_hand_thumb_rota_link1"/>
        <!-- <geom type="mesh" rgba="1 1 1 1" mesh="left_hand_thumb_rota_link1"/> -->
        <body name="left_hand_thumb_rota_link2" pos="0.0553 0 0">
          <inertial pos="0.022453 0.000690615 0.00314279" quat="0.0604384 0.713745 -0.0199601 0.697508" mass="0.037401" diaginertia="9.54694e-06 8.27053e-06 3.92141e-06"/>
          <joint name="left_hand_thumb_rota_joint2" pos="0 0 0" axis="0 1 0" range="-0.17 1.83" actuatorfrcrange="-0.4 0.4" damping="1" frictionloss="1"/>
          <geom type="mesh" contype="0" conaffinity="0" group="1" density="0" rgba="0.384314 0.384314 0.384314 1" mesh="left_hand_thumb_rota_link2"/>
          <geom type="mesh" rgba="0.384314 0.384314 0.384314 1" mesh="left_hand_thumb_rota_link2"/>
          <geom pos="0.0504017 0 0" quat="1 0 0 0" type="mesh" contype="0" conaffinity="0" group="1" density="0" rgba="0.698039 0.698039 0.698039 1" mesh="left_hand_thumb_rota_tip"/>
          <geom pos="0.0504017 0 0" quat="1 0 0 0" type="mesh" rgba="0.698039 0.698039 0.698039 1" mesh="left_hand_thumb_rota_tip"/>
        </body>
      </body>
    </body>
    <body name="left_hand_index_bend_link" pos="0.0265 -0.0065 -0.0899">
      <inertial pos="-0.000134545 -0.000675884 0.00420851" quat="0.999797 0.0190041 0.00232573 0.00634399" mass="0.0677836" diaginertia="2.16573e-05 2.09935e-05 3.36931e-06"/>
      <joint name="left_hand_index_bend_joint" pos="0 0 0" axis="0 -1 0" range="-0.175 0.175" actuatorfrcrange="-0.4 0.4" damping="1" frictionloss="1"/>
      <geom type="mesh" contype="0" conaffinity="0" group="1" density="0" rgba="0.988235 0.737255 0.517647 1" mesh="left_hand_index_bend_link"/>
      <!-- <geom type="mesh" rgba="0.988235 0.737255 0.517647 1" mesh="left_hand_index_bend_link"/> -->
      <body name="left_hand_index_rota_link1" pos="0 0 -0.0178">
        <inertial pos="0.000139769 0.000800517 -0.0356039" quat="0.999865 -0.00809181 0.0131314 0.00566203" mass="0.0630216" diaginertia="2.05301e-05 1.92461e-05 4.135e-06"/>
        <joint name="left_hand_index_joint1" pos="0 0 0" axis="-1 0 0" range="0 1.92" actuatorfrcrange="-1.1 1.1" damping="1" frictionloss="1"/>
        <geom type="mesh" contype="0" conaffinity="0" group="1" density="0" rgba="1 1 1 1" mesh="left_hand_index_rota_link1"/>
        <!-- <geom type="mesh" rgba="1 1 1 1" mesh="left_hand_index_rota_link1"/> -->
        <body name="left_hand_index_rota_link2" pos="0 0 -0.0558">
          <inertial pos="0.000338569 -1.93676e-05 -0.0231329" quat="0.935383 -0.00588963 0.0260882 0.352623" mass="0.0179923" diaginertia="3.02411e-06 3.01969e-06 9.82703e-07"/>
          <joint name="left_hand_index_joint2" pos="0 0 0" axis="-1 0 0" range="0 1.92" actuatorfrcrange="-0.4 0.4" damping="1" frictionloss="1"/>
          <geom type="mesh" contype="0" conaffinity="0" group="1" density="0" rgba="0.866667 0.866667 0.890196 1" mesh="left_hand_index_rota_link2"/>
          <geom type="mesh" rgba="0.866667 0.866667 0.890196 1" mesh="left_hand_index_rota_link2"/>
          <geom pos="0 0 -0.0425" quat="1 0 0 0" type="mesh" contype="0" conaffinity="0" group="1" density="0" rgba="0.698039 0.698039 0.698039 1" mesh="left_hand_index_rota_tip"/>
          <geom pos="0 0 -0.0425" quat="1 0 0 0" type="mesh" rgba="0.698039 0.698039 0.698039 1" mesh="left_hand_index_rota_tip"/>
        </body>
      </body>
    </body>
    <body name="left_hand_mid_link1" pos="0.004 -0.0065 -0.1082">
      <inertial pos="0.00013977 0.000800517 -0.0356039" quat="0.999865 -0.00809181 0.0131314 0.00566198" mass="0.0630216" diaginertia="2.05301e-05 1.92461e-05 4.135e-06"/>
      <joint name="left_hand_mid_joint1" pos="0 0 0" axis="-1 0 0" range="0 1.92" actuatorfrcrange="-1.1 1.1" damping="1" frictionloss="1"/>
      <geom type="mesh" contype="0" conaffinity="0" group="1" density="0" rgba="1 1 1 1" mesh="left_hand_mid_link1"/>
      <!-- <geom type="mesh" rgba="1 1 1 1" mesh="left_hand_mid_link1"/> -->
      <body name="left_hand_mid_link2" pos="0 0 -0.0558">
        <inertial pos="0.000338571 -1.93625e-05 -0.0231329" quat="0.935371 -0.00588853 0.0260882 0.352656" mass="0.0179923" diaginertia="3.02411e-06 3.01969e-06 9.82702e-07"/>
        <joint name="left_hand_mid_joint2" pos="0 0 0" axis="-1 0 0" range="0 1.92" actuatorfrcrange="-0.4 0.4" damping="1" frictionloss="1"/>
        <geom type="mesh" contype="0" conaffinity="0" group="1" density="0" rgba="0.866667 0.866667 0.890196 1" mesh="left_hand_mid_link2"/>
        <geom type="mesh" rgba="0.866667 0.866667 0.890196 1" mesh="left_hand_mid_link2"/>
        <geom pos="0 0 -0.0425" quat="1 0 0 0" type="mesh" contype="0" conaffinity="0" group="1" density="0" rgba="0.698039 0.698039 0.698039 1" mesh="left_hand_mid_tip"/>
        <geom pos="0 0 -0.0425" quat="1 0 0 0" type="mesh" rgba="0.698039 0.698039 0.698039 1" mesh="left_hand_mid_tip"/>
      </body>
    </body>
    <body name="left_hand_ring_link1" pos="-0.016 -0.0065 -0.1052">
      <inertial pos="0.00013977 0.000800517 -0.0356039" quat="0.999865 -0.00809184 0.0131314 0.00566198" mass="0.0630216" diaginertia="2.05301e-05 1.92461e-05 4.13501e-06"/>
      <joint name="left_hand_ring_joint1" pos="0 0 0" axis="-1 0 0" range="0 1.92" actuatorfrcrange="-1.1 1.1" damping="1" frictionloss="1"/>
      <geom type="mesh" contype="0" conaffinity="0" group="1" density="0" rgba="1 1 1 1" mesh="left_hand_ring_link1"/>
      <!-- <geom type="mesh" rgba="1 1 1 1" mesh="left_hand_ring_link1"/> -->
      <body name="left_hand_ring_link2" pos="0 0 -0.0558">
        <inertial pos="0.000338569 -1.93675e-05 -0.0231329" quat="0.935383 -0.00588963 0.0260882 0.352623" mass="0.0179923" diaginertia="3.02411e-06 3.01969e-06 9.82703e-07"/>
        <joint name="left_hand_ring_joint2" pos="0 0 0" axis="-1 0 0" range="0 1.92" actuatorfrcrange="-0.4 0.4" damping="1" frictionloss="1"/>
        <geom type="mesh" contype="0" conaffinity="0" group="1" density="0" rgba="0.866667 0.866667 0.890196 1" mesh="left_hand_ring_link2"/>
        <geom type="mesh" rgba="0.866667 0.866667 0.890196 1" mesh="left_hand_ring_link2"/>
        <geom pos="0 0 -0.0425" quat="1 0 0 0" type="mesh" contype="0" conaffinity="0" group="1" density="0" rgba="0.698039 0.698039 0.698039 1" mesh="left_hand_ring_tip"/>
        <geom pos="0 0 -0.0425" quat="1 0 0 0" type="mesh" rgba="0.698039 0.698039 0.698039 1" mesh="left_hand_ring_tip"/>
      </body>
    </body>
    <body name="left_hand_pinky_link1" pos="-0.036 -0.0065 -0.1022">
      <inertial pos="0.000139769 0.000800517 -0.0356039" quat="0.999865 -0.00809183 0.0131314 0.00566202" mass="0.0630216" diaginertia="2.05301e-05 1.92461e-05 4.135e-06"/>
      <joint name="left_hand_pinky_joint1" pos="0 0 0" axis="-1 0 0" range="0 1.92" actuatorfrcrange="-1.1 1.1" damping="1" frictionloss="1"/>
      <geom type="mesh" contype="0" conaffinity="0" group="1" density="0" rgba="1 1 1 1" mesh="left_hand_pinky_link1"/>
      <!-- <geom type="mesh" rgba="1 1 1 1" mesh="left_hand_pinky_link1"/> -->
      <body name="left_hand_pinky_link2" pos="0 0 -0.0558">
        <inertial pos="0.000338573 -1.93618e-05 -0.0231329" quat="0.935376 -0.00588888 0.026088 0.352643" mass="0.0179923" diaginertia="3.0241e-06 3.01969e-06 9.82702e-07"/>
        <joint name="left_hand_pinky_joint2" pos="0 0 0" axis="-1 0 0" range="0 1.92" actuatorfrcrange="-0.4 0.4" damping="1" frictionloss="1"/>
        <geom type="mesh" contype="0" conaffinity="0" group="1" density="0" rgba="0.866667 0.866667 0.890196 1" mesh="left_hand_pinky_link2"/>
        <geom type="mesh" rgba="0.866667 0.866667 0.890196 1" mesh="left_hand_pinky_link2"/>
        <geom pos="0 0 -0.0425" quat="1 0 0 0" type="mesh" contype="0" conaffinity="0" group="1" density="0" rgba="0.698039 0.698039 0.698039 1" mesh="left_hand_pinky_tip"/>
        <geom pos="0 0 -0.0425" quat="1 0 0 0" type="mesh" rgba="0.698039 0.698039 0.698039 1" mesh="left_hand_pinky_tip"/>
      </body>
    </body>
  </worldbody>
</mujoco>
