<mujoco model="xhand_right">
  <compiler angle="radian" meshdir="./meshes/"/>

  <asset>
    <mesh name="right_hand_link" file="right_hand_link.STL"/>
    <mesh name="right_hand_ee_link" file="right_hand_ee_link.STL"/>
    <mesh name="right_hand_thumb_bend_link" file="right_hand_thumb_bend_link.STL"/>
    <mesh name="right_hand_thumb_rota_link1" file="right_hand_thumb_rota_link1.STL"/>
    <mesh name="right_hand_thumb_rota_link2" file="right_hand_thumb_rota_link2.STL"/>
    <mesh name="right_hand_thumb_rota_tip" file="right_hand_thumb_rota_tip.STL"/>
    <mesh name="right_hand_index_bend_link" file="right_hand_index_bend_link.STL"/>
    <mesh name="right_hand_index_rota_link1" file="right_hand_index_rota_link1.STL"/>
    <mesh name="right_hand_index_rota_link2" file="right_hand_index_rota_link2.STL"/>
    <mesh name="right_hand_index_rota_tip" file="right_hand_index_rota_tip.STL"/>
    <mesh name="right_hand_mid_link1" file="right_hand_mid_link1.STL"/>
    <mesh name="right_hand_mid_link2" file="right_hand_mid_link2.STL"/>
    <mesh name="right_hand_mid_tip" file="right_hand_mid_tip.STL"/>
    <mesh name="right_hand_ring_link1" file="right_hand_ring_link1.STL"/>
    <mesh name="right_hand_ring_link2" file="right_hand_ring_link2.STL"/>
    <mesh name="right_hand_ring_tip" file="right_hand_ring_tip.STL"/>
    <mesh name="right_hand_pinky_link1" file="right_hand_pinky_link1.STL"/>
    <mesh name="right_hand_pinky_link2" file="right_hand_pinky_link2.STL"/>
    <mesh name="right_hand_pinky_tip" file="right_hand_pinky_tip.STL"/>
  </asset>

  <worldbody>
    <geom type="mesh" contype="0" conaffinity="0" group="1" density="0" rgba="0.792157 0.819608 0.933333 1" mesh="right_hand_link"/>
    <geom type="mesh" rgba="0.792157 0.819608 0.933333 1" mesh="right_hand_link"/>
    <geom pos="0 0 -0.065" quat="1 0 0 0" type="mesh" contype="0" conaffinity="0" group="1" density="0" rgba="0.698039 0.698039 0.698039 1" mesh="right_hand_ee_link"/>
    <geom pos="0 0 -0.065" quat="1 0 0 0" type="mesh" rgba="0.698039 0.698039 0.698039 1" mesh="right_hand_ee_link"/>
    <body name="right_hand_thumb_bend_link" pos="0.0228 0.0095 -0.0305">
      <inertial pos="0.0145291 -0.000901303 -0.000127926" quat="0.0288921 0.68936 0.0166971 0.72365" mass="0.00985529" diaginertia="1.30647e-06 1.29142e-06 5.40953e-07"/>
      <joint name="right_hand_thumb_bend_joint" pos="0 0 0" axis="0 0 1" range="0 1.83" actuatorfrcrange="-1.1 1.1" damping="1" frictionloss="1"/>
      <geom type="mesh" contype="0" conaffinity="0" group="1" density="0" rgba="0.890196 0.890196 0.913725 1" mesh="right_hand_thumb_bend_link"/>
      <!-- <geom type="mesh" rgba="0.890196 0.890196 0.913725 1" mesh="right_hand_thumb_bend_link"/> -->
      <body name="right_hand_thumb_rota_link1" pos="0.028599 0.0083177 0.00178" quat="0.99124 0.130499 0.00265603 0.0201745">
        <inertial pos="0.0279237 -0.000127603 -0.000272577" quat="-0.0989965 0.703671 0.0850598 0.698435" mass="0.153265" diaginertia="5.62327e-05 4.89801e-05 2.23924e-05"/>
        <joint name="right_hand_thumb_rota_joint1" pos="0 0 0" axis="0 1 0" range="-1.05 1.57" actuatorfrcrange="-1.1 1.1" damping="1" frictionloss="1"/>
        <geom type="mesh" contype="0" conaffinity="0" group="1" density="0" rgba="1 1 1 1" mesh="right_hand_thumb_rota_link1"/>
        <geom type="mesh" rgba="1 1 1 1" mesh="right_hand_thumb_rota_link1"/>
        <body name="right_hand_thumb_rota_link2" pos="0.0553 0 0">
          <inertial pos="0.0224697 -0.000691342 0.00302232" quat="-0.0604027 0.715612 0.0198065 0.695599" mass="0.0374004" diaginertia="9.54653e-06 8.2702e-06 3.92137e-06"/>
          <joint name="right_hand_thumb_rota_joint2" pos="0 0 0" axis="0 1 0" range="-0.175 1.83" actuatorfrcrange="-0.4 0.4" damping="1" frictionloss="1"/>
          <geom type="mesh" contype="0" conaffinity="0" group="1" density="0" rgba="0.792157 0.819608 0.933333 1" mesh="right_hand_thumb_rota_link2"/>
          <geom type="mesh" rgba="0.792157 0.819608 0.933333 1" mesh="right_hand_thumb_rota_link2"/>
          <geom pos="0.0504025 0 0" quat="1 0 0 0" type="mesh" contype="0" conaffinity="0" group="1" density="0" rgba="0.698039 0.698039 0.698039 1" mesh="right_hand_thumb_rota_tip"/>
          <geom pos="0.0504025 0 0" quat="1 0 0 0" type="mesh" rgba="0.698039 0.698039 0.698039 1" mesh="right_hand_thumb_rota_tip"/>
        </body>
      </body>
    </body>
    <body name="right_hand_index_bend_link" pos="0.0265 0.0065 -0.0899">
      <inertial pos="8.08449e-05 0.000675884 0.00420851" quat="0.999802 -0.0189928 -0.00582288 0.000998418" mass="0.0677836" diaginertia="2.16592e-05 2.09943e-05 3.36803e-06"/>
      <joint name="right_hand_index_bend_joint" pos="0 0 0" axis="0 -1 0" range="-0.175 0.175" actuatorfrcrange="-0.4 0.4" damping="1" frictionloss="1"/>
      <geom type="mesh" contype="0" conaffinity="0" group="1" density="0" rgba="0.439216 0.439216 0.439216 1" mesh="right_hand_index_bend_link"/>
      <!-- <geom type="mesh" rgba="0.439216 0.439216 0.439216 1" mesh="right_hand_index_bend_link"/> -->
      <body name="right_hand_index_rota_link1" pos="0 0 -0.0178">
        <inertial pos="-0.00013977 -0.000800517 -0.0356039" quat="0.999865 0.00809183 -0.0131314 0.00566198" mass="0.0630216" diaginertia="2.05301e-05 1.92461e-05 4.135e-06"/>
        <joint name="right_hand_index_joint1" pos="0 0 0" axis="1 0 0" range="0 1.92" actuatorfrcrange="-1.1 1.1" damping="1" frictionloss="1"/>
        <geom type="mesh" contype="0" conaffinity="0" group="1" density="0" rgba="1 1 1 1" mesh="right_hand_index_rota_link1"/>
        <geom type="mesh" rgba="1 1 1 1" mesh="right_hand_index_rota_link1"/>
        <body name="right_hand_index_rota_link2" pos="0 0 -0.0558">
          <inertial pos="-0.000338569 1.93676e-05 -0.0231329" quat="0.935383 0.00588963 -0.0260882 0.352623" mass="0.0179923" diaginertia="3.02411e-06 3.01969e-06 9.82703e-07"/>
          <joint name="right_hand_index_joint2" pos="0 0 0" axis="1 0 0" range="0 1.92" actuatorfrcrange="-0.4 0.4" damping="1" frictionloss="1"/>
          <geom type="mesh" contype="0" conaffinity="0" group="1" density="0" rgba="0.866667 0.866667 0.890196 1" mesh="right_hand_index_rota_link2"/>
          <geom type="mesh" rgba="0.866667 0.866667 0.890196 1" mesh="right_hand_index_rota_link2"/>
          <geom pos="0 0 -0.0425" quat="1 0 0 0" type="mesh" contype="0" conaffinity="0" group="1" density="0" rgba="0.698039 0.698039 0.698039 1" mesh="right_hand_index_rota_tip"/>
          <geom pos="0 0 -0.0425" quat="1 0 0 0" type="mesh" rgba="0.698039 0.698039 0.698039 1" mesh="right_hand_index_rota_tip"/>
        </body>
      </body>
    </body>
    <body name="right_hand_mid_link1" pos="0.004 0.0065 -0.1082">
      <inertial pos="-0.000139769 -0.000800517 -0.0356039" quat="0.999865 0.00809181 -0.0131314 0.00566199" mass="0.0630216" diaginertia="2.05301e-05 1.92461e-05 4.135e-06"/>
      <joint name="right_hand_mid_joint1" pos="0 0 0" axis="1 0 0" range="0 1.92" actuatorfrcrange="-1.1 1.1" damping="1" frictionloss="1"/>
      <geom type="mesh" contype="0" conaffinity="0" group="1" density="0" rgba="1 1 1 1" mesh="right_hand_mid_link1"/>
      <!-- <geom type="mesh" rgba="1 1 1 1" mesh="right_hand_mid_link1"/> -->
      <body name="right_hand_mid_link2" pos="0 0 -0.0558">
        <inertial pos="-0.000338569 1.93676e-05 -0.0231329" quat="0.935383 0.00588963 -0.0260882 0.352623" mass="0.0179923" diaginertia="3.02411e-06 3.01969e-06 9.82703e-07"/>
        <joint name="right_hand_mid_joint2" pos="0 0 0" axis="1 0 0" range="0 1.94" actuatorfrcrange="-0.4 0.4" damping="1" frictionloss="1"/>
        <geom type="mesh" contype="0" conaffinity="0" group="1" density="0" rgba="0.866667 0.866667 0.890196 1" mesh="right_hand_mid_link2"/>
        <geom type="mesh" rgba="0.866667 0.866667 0.890196 1" mesh="right_hand_mid_link2"/>
        <geom pos="0 0 -0.042107" quat="1 0 0 0" type="mesh" contype="0" conaffinity="0" group="1" density="0" rgba="0.698039 0.698039 0.698039 1" mesh="right_hand_mid_tip"/>
        <geom pos="0 0 -0.042107" quat="1 0 0 0" type="mesh" rgba="0.698039 0.698039 0.698039 1" mesh="right_hand_mid_tip"/>
      </body>
    </body>
    <body name="right_hand_ring_link1" pos="-0.016 0.0065 -0.1052">
      <inertial pos="-0.00013977 -0.000800517 -0.0356039" quat="0.999865 0.00809183 -0.0131314 0.00566196" mass="0.0630216" diaginertia="2.05301e-05 1.92461e-05 4.135e-06"/>
      <joint name="right_hand_ring_joint1" pos="0 0 0" axis="1 0 0" range="0 1.92" actuatorfrcrange="-1.1 1.1" damping="1" frictionloss="1"/>
      <geom type="mesh" contype="0" conaffinity="0" group="1" density="0" rgba="1 1 1 1" mesh="right_hand_ring_link1"/>
      <!-- <geom type="mesh" rgba="1 1 1 1" mesh="right_hand_ring_link1"/> -->
      <body name="right_hand_ring_link2" pos="0 0 -0.0558">
        <inertial pos="-0.000338572 1.93622e-05 -0.0231329" quat="0.935371 0.00588858 -0.0260881 0.352655" mass="0.0179923" diaginertia="3.02411e-06 3.01969e-06 9.82702e-07"/>
        <joint name="right_hand_ring_joint2" pos="0 0 0" axis="1 0 0" range="0 1.92" actuatorfrcrange="-0.4 0.4" damping="1" frictionloss="1"/>
        <geom type="mesh" contype="0" conaffinity="0" group="1" density="0" rgba="0.866667 0.866667 0.890196 1" mesh="right_hand_ring_link2"/>
        <geom type="mesh" rgba="0.866667 0.866667 0.890196 1" mesh="right_hand_ring_link2"/>
        <geom pos="0 0 -0.0425" quat="1 0 0 0" type="mesh" contype="0" conaffinity="0" group="1" density="0" rgba="0.698039 0.698039 0.698039 1" mesh="right_hand_ring_tip"/>
        <geom pos="0 0 -0.0425" quat="1 0 0 0" type="mesh" rgba="0.698039 0.698039 0.698039 1" mesh="right_hand_ring_tip"/>
      </body>
    </body>
    <body name="right_hand_pinky_link1" pos="-0.036 0.0065 -0.1022">
      <inertial pos="-0.000139769 -0.000800517 -0.0356039" quat="0.999865 0.00809181 -0.0131314 0.00566204" mass="0.0630216" diaginertia="2.05301e-05 1.92461e-05 4.135e-06"/>
      <joint name="right_hand_pinky_joint1" pos="0 0 0" axis="1 0 0" range="0 1.92" actuatorfrcrange="-1.1 1.1" damping="1" frictionloss="1"/>
      <geom type="mesh" contype="0" conaffinity="0" group="1" density="0" rgba="1 1 1 1" mesh="right_hand_pinky_link1"/>
      <!-- <geom type="mesh" rgba="1 1 1 1" mesh="right_hand_pinky_link1"/> -->
      <body name="right_hand_pinky_link2" pos="0 0 -0.0558">
        <inertial pos="-0.000338569 1.93676e-05 -0.0231329" quat="0.935383 0.00588963 -0.0260882 0.352623" mass="0.0179923" diaginertia="3.02411e-06 3.01969e-06 9.82703e-07"/>
        <joint name="right_hand_pinky_joint2" pos="0 0 0" axis="1 0 0" range="0 1.92" actuatorfrcrange="-0.4 0.4" damping="1" frictionloss="1"/>
        <geom type="mesh" contype="0" conaffinity="0" group="1" density="0" rgba="0.866667 0.866667 0.890196 1" mesh="right_hand_pinky_link2"/>
        <geom type="mesh" rgba="0.866667 0.866667 0.890196 1" mesh="right_hand_pinky_link2"/>
        <geom pos="0 0 -0.0425" quat="1 0 0 0" type="mesh" contype="0" conaffinity="0" group="1" density="0" rgba="0.698039 0.698039 0.698039 1" mesh="right_hand_pinky_tip"/>
        <geom pos="0 0 -0.0425" quat="1 0 0 0" type="mesh" rgba="0.698039 0.698039 0.698039 1" mesh="right_hand_pinky_tip"/>
      </body>
    </body>
  </worldbody>
</mujoco>
