<mujoco model="xhand_left">
  <compiler angle="radian" meshdir="./meshes/"/>

  <asset>
    <mesh name="left_hand_link" file="left_hand_link.STL"/>
    <mesh name="left_hand_ee_link" file="left_hand_ee_link.STL"/>
    <mesh name="left_hand_thumb_bend_link" file="left_hand_thumb_bend_link.STL"/>
    <mesh name="left_hand_thumb_rota_link1" file="left_hand_thumb_rota_link1.STL"/>
    <mesh name="left_hand_thumb_rota_link2" file="left_hand_thumb_rota_link2.STL"/>
    <mesh name="left_hand_thumb_rota_tip" file="left_hand_thumb_rota_tip.STL"/>
    <mesh name="left_hand_index_bend_link" file="left_hand_index_bend_link.STL"/>
    <mesh name="left_hand_index_rota_link1" file="left_hand_index_rota_link1.STL"/>
    <mesh name="left_hand_index_rota_link2" file="left_hand_index_rota_link2.STL"/>
    <mesh name="left_hand_index_rota_tip" file="left_hand_index_rota_tip.STL"/>
    <mesh name="left_hand_mid_link1" file="left_hand_mid_link1.STL"/>
    <mesh name="left_hand_mid_link2" file="left_hand_mid_link2.STL"/>
    <mesh name="left_hand_mid_tip" file="left_hand_mid_tip.STL"/>
    <mesh name="left_hand_ring_link1" file="left_hand_ring_link1.STL"/>
    <mesh name="left_hand_ring_link2" file="left_hand_ring_link2.STL"/>
    <mesh name="left_hand_ring_tip" file="left_hand_ring_tip.STL"/>
    <mesh name="left_hand_pinky_link1" file="left_hand_pinky_link1.STL"/>
    <mesh name="left_hand_pinky_link2" file="left_hand_pinky_link2.STL"/>
    <mesh name="left_hand_pinky_tip" file="left_hand_pinky_tip.STL"/>
  </asset>

  <worldbody>
    <geom type="mesh" contype="0" conaffinity="0" group="1" density="0" rgba="0.792157 0.819608 0.933333 1" mesh="left_hand_link"/>
    <geom type="mesh" rgba="0.792157 0.819608 0.933333 1" mesh="left_hand_link"/>
    <geom pos="0 0 -0.065" quat="1 0 0 0" type="mesh" contype="0" conaffinity="0" group="1" density="0" rgba="0.698039 0.698039 0.698039 1" mesh="left_hand_ee_link"/>
    <geom pos="0 0 -0.065" quat="1 0 0 0" type="mesh" rgba="0.698039 0.698039 0.698039 1" mesh="left_hand_ee_link"/>
    <body name="left_hand_thumb_bend_link" pos="0.0228 -0.0095 -0.0305">
      <inertial pos="0.0146951 0.00101706 0.000731323" quat="0.992393 -0.0973709 0.0612459 -0.0438671" mass="0.00988789" diaginertia="3.62054e-07 2.30437e-07 2.08786e-07"/>
      <joint name="left_hand_thumb_bend_joint" pos="0 0 0" axis="0 0 -1" range="0 1.83" actuatorfrcrange="-1.1 1.1" damping="1" frictionloss="1"/>
      <geom type="mesh" contype="0" conaffinity="0" group="1" density="0" rgba="0.615686 0.643137 0.67451 1" mesh="left_hand_thumb_bend_link"/>
      <body name="left_hand_thumb_rota_link1" pos="0.0285986 -0.00831766 0.00177996" quat="0.99124 -0.130499 0.00265604 -0.0201746">
        <inertial pos="0.028791 -0.000242916 0.00247392" quat="0.217829 0.653076 -0.217073 0.692042" mass="0.153155" diaginertia="3.52828e-05 2.86923e-05 2.73828e-05"/>
        <joint name="left_hand_thumb_rota_joint1" pos="0 0 0" axis="0 1 0" range="-1.05 1.57" actuatorfrcrange="-1.1 1.1" damping="1" frictionloss="1"/>
        <geom type="mesh" contype="0" conaffinity="0" group="1" density="0" rgba="1 1 1 1" mesh="left_hand_thumb_rota_link1"/>
        <geom type="mesh" rgba="1 1 1 1" mesh="left_hand_thumb_rota_link1"/>
        <body name="left_hand_thumb_rota_link2" pos="0.0553 0 0">
          <inertial pos="0.0246456 2.69138e-05 0.00357064" quat="0.00187299 0.759205 0.00176869 0.650847" mass="0.0374006" diaginertia="8.09648e-06 6.84881e-06 3.82956e-06"/>
          <joint name="left_hand_thumb_rota_joint2" pos="0 0 0" axis="0 1 0" range="-0.17 1.83" actuatorfrcrange="-0.4 0.4" damping="1" frictionloss="1"/>
          <geom type="mesh" contype="0" conaffinity="0" group="1" density="0" rgba="0.384314 0.384314 0.384314 1" mesh="left_hand_thumb_rota_link2"/>
          <geom type="mesh" rgba="0.384314 0.384314 0.384314 1" mesh="left_hand_thumb_rota_link2"/>
          <geom pos="0.0504025 0 0" quat="1 0 0 0" type="mesh" contype="0" conaffinity="0" group="1" density="0" rgba="0.698039 0.698039 0.698039 1" mesh="left_hand_thumb_rota_tip"/>
          <geom pos="0.0504025 0 0" quat="1 0 0 0" type="mesh" rgba="0.698039 0.698039 0.698039 1" mesh="left_hand_thumb_rota_tip"/>
        </body>
      </body>
    </body>
    <body name="left_hand_index_bend_link" pos="0.0265 -0.0065 -0.0899">
      <inertial pos="-1.36538e-05 -0.000296873 0.00896969" quat="0.997151 0.0753904 0.00111959 -0.00217774" mass="0.0678358" diaginertia="1.2458e-05 1.17987e-05 3.93143e-06"/>
      <joint name="left_hand_index_bend_joint" pos="0 0 0" axis="0 -1 0" range="-0.175 0.175" actuatorfrcrange="-0.4 0.4" damping="1" frictionloss="1"/>
      <geom type="mesh" contype="0" conaffinity="0" group="1" density="0" rgba="1 1 1 1" mesh="left_hand_index_bend_link"/>
      <body name="left_hand_index_rota_link1" pos="0 0 -0.0178">
        <inertial pos="-1.33093e-05 0.00117935 -0.0314668" quat="0.999972 -0.00501877 0.0036222 0.00411164" mass="0.0630023" diaginertia="1.27462e-05 1.13166e-05 3.96726e-06"/>
        <joint name="left_hand_index_joint1" pos="0 0 0" axis="-1 0 0" range="0 1.92" actuatorfrcrange="-1.1 1.1" damping="1" frictionloss="1"/>
        <geom type="mesh" contype="0" conaffinity="0" group="1" density="0" rgba="1 1 1 1" mesh="left_hand_index_rota_link1"/>
        <geom type="mesh" rgba="1 1 1 1" mesh="left_hand_index_rota_link1"/>
        <body name="left_hand_index_rota_link2" pos="0 0 -0.0558">
          <inertial pos="0.000105985 0.000552346 -0.0269534" quat="0.999776 -0.00709054 0.0176373 0.00935454" mass="0.0179783" diaginertia="1.57535e-06 1.41212e-06 9.24998e-07"/>
          <joint name="left_hand_index_joint2" pos="0 0 0" axis="-1 0 0" range="0 1.92" actuatorfrcrange="-0.4 0.4" damping="1" frictionloss="1"/>
          <geom type="mesh" contype="0" conaffinity="0" group="1" density="0" rgba="0.866667 0.866667 0.890196 1" mesh="left_hand_index_rota_link2"/>
          <geom type="mesh" rgba="0.866667 0.866667 0.890196 1" mesh="left_hand_index_rota_link2"/>
          <geom pos="0 0 -0.0425" quat="1 0 0 0" type="mesh" contype="0" conaffinity="0" group="1" density="0" rgba="0.698039 0.698039 0.698039 1" mesh="left_hand_index_rota_tip"/>
          <geom pos="0 0 -0.0425" quat="1 0 0 0" type="mesh" rgba="0.698039 0.698039 0.698039 1" mesh="left_hand_index_rota_tip"/>
        </body>
      </body>
    </body>
    <body name="left_hand_mid_link1" pos="0.004 -0.0065 -0.1082">
      <inertial pos="-1.33093e-05 0.00117935 -0.0314668" quat="0.999972 -0.00501877 0.00362222 0.00411166" mass="0.0630023" diaginertia="1.27462e-05 1.13166e-05 3.96726e-06"/>
      <joint name="left_hand_mid_joint1" pos="0 0 0" axis="-1 0 0" range="0 1.92" actuatorfrcrange="-1.1 1.1" damping="1" frictionloss="1"/>
      <geom type="mesh" contype="0" conaffinity="0" group="1" density="0" rgba="1 1 1 1" mesh="left_hand_mid_link1"/>
      <geom type="mesh" rgba="1 1 1 1" mesh="left_hand_mid_link1"/>
      <body name="left_hand_mid_link2" pos="0 0 -0.0558">
        <inertial pos="0.000105985 0.000552346 -0.0269534" quat="0.999776 -0.00709054 0.0176373 0.00935454" mass="0.0179783" diaginertia="1.57535e-06 1.41212e-06 9.24998e-07"/>
        <joint name="left_hand_mid_joint2" pos="0 0 0" axis="-1 0 0" range="0 1.92" actuatorfrcrange="-0.4 0.4" damping="1" frictionloss="1"/>
        <geom type="mesh" contype="0" conaffinity="0" group="1" density="0" rgba="0.866667 0.866667 0.890196 1" mesh="left_hand_mid_link2"/>
        <geom type="mesh" rgba="0.866667 0.866667 0.890196 1" mesh="left_hand_mid_link2"/>
        <geom pos="0 0 -0.0425" quat="1 0 0 0" type="mesh" contype="0" conaffinity="0" group="1" density="0" rgba="0.698039 0.698039 0.698039 1" mesh="left_hand_mid_tip"/>
        <geom pos="0 0 -0.0425" quat="1 0 0 0" type="mesh" rgba="0.698039 0.698039 0.698039 1" mesh="left_hand_mid_tip"/>
      </body>
    </body>
    <body name="left_hand_ring_link1" pos="-0.016 -0.0065 -0.1052">
      <inertial pos="-1.33096e-05 0.00117935 -0.0314668" quat="0.999972 -0.00501874 0.00362221 0.00411173" mass="0.0630023" diaginertia="1.27462e-05 1.13166e-05 3.96726e-06"/>
      <joint name="left_hand_ring_joint1" pos="0 0 0" axis="-1 0 0" range="0 1.92" actuatorfrcrange="-1.1 1.1" damping="1" frictionloss="1"/>
      <geom type="mesh" contype="0" conaffinity="0" group="1" density="0" rgba="1 1 1 1" mesh="left_hand_ring_link1"/>
      <geom type="mesh" rgba="1 1 1 1" mesh="left_hand_ring_link1"/>
      <body name="left_hand_ring_link2" pos="0 0 -0.0558">
        <inertial pos="0.000105985 0.000552346 -0.0269534" quat="0.999776 -0.00709054 0.0176373 0.00935454" mass="0.0179783" diaginertia="1.57535e-06 1.41212e-06 9.24998e-07"/>
        <joint name="left_hand_ring_joint2" pos="0 0 0" axis="-1 0 0" range="0 1.92" actuatorfrcrange="-0.4 0.4" damping="1" frictionloss="1"/>
        <geom type="mesh" contype="0" conaffinity="0" group="1" density="0" rgba="0.866667 0.866667 0.890196 1" mesh="left_hand_ring_link2"/>
        <geom type="mesh" rgba="0.866667 0.866667 0.890196 1" mesh="left_hand_ring_link2"/>
        <geom pos="0 0 -0.0425" quat="1 0 0 0" type="mesh" contype="0" conaffinity="0" group="1" density="0" rgba="0.698039 0.698039 0.698039 1" mesh="left_hand_ring_tip"/>
        <geom pos="0 0 -0.0425" quat="1 0 0 0" type="mesh" rgba="0.698039 0.698039 0.698039 1" mesh="left_hand_ring_tip"/>
      </body>
    </body>
    <body name="left_hand_pinky_link1" pos="-0.036 -0.0065 -0.1022">
      <inertial pos="-1.33097e-05 0.00117935 -0.0314668" quat="0.999972 -0.00501872 0.0036222 0.00411174" mass="0.0630023" diaginertia="1.27462e-05 1.13166e-05 3.96726e-06"/>
      <joint name="left_hand_pinky_joint1" pos="0 0 0" axis="-1 0 0" range="0 1.92" actuatorfrcrange="-1.1 1.1" damping="1" frictionloss="1"/>
      <geom type="mesh" contype="0" conaffinity="0" group="1" density="0" rgba="1 1 1 1" mesh="left_hand_pinky_link1"/>
      <geom type="mesh" rgba="1 1 1 1" mesh="left_hand_pinky_link1"/>
      <body name="left_hand_pinky_link2" pos="0 0 -0.0558">
        <inertial pos="0.000105985 0.000552346 -0.0269534" quat="0.999776 -0.00709054 0.0176373 0.00935454" mass="0.0179783" diaginertia="1.57535e-06 1.41212e-06 9.24998e-07"/>
        <joint name="left_hand_pinky_joint2" pos="0 0 0" axis="-1 0 0" range="0 1.92" actuatorfrcrange="-0.4 0.4" damping="1" frictionloss="1"/>
        <geom type="mesh" contype="0" conaffinity="0" group="1" density="0" rgba="0.866667 0.866667 0.890196 1" mesh="left_hand_pinky_link2"/>
        <geom type="mesh" rgba="0.866667 0.866667 0.890196 1" mesh="left_hand_pinky_link2"/>
        <geom pos="0 0 -0.0425" quat="1 0 0 0" type="mesh" contype="0" conaffinity="0" group="1" density="0" rgba="0.698039 0.698039 0.698039 1" mesh="left_hand_pinky_tip"/>
        <geom pos="0 0 -0.0425" quat="1 0 0 0" type="mesh" rgba="0.698039 0.698039 0.698039 1" mesh="left_hand_pinky_tip"/>
      </body>
    </body>
  </worldbody>
</mujoco>
