<?xml version="1.0" encoding="utf-8"?>
<!-- This URDF was automatically created by SolidWorks to URDF Exporter! Originally created by Stephen Brawner (brawner@gmail.com) 
     Commit Version: 1.6.0-4-g7f85cfe  Build Version: 1.6.7995.38578
     For more information, please see http://wiki.ros.org/sw_urdf_exporter -->
<robot name="xhand_left">
  <mujoco>
    <compiler meshdir="./meshes/" balanceinertia="true" discardvisual="false" />
  </mujoco>
  <link name="base_link">
  </link>
  <joint name="base_link_joint" type="fixed">
    <origin xyz="0 0 0.0" rpy="0 0 0" />
    <parent link="base_link" />
    <child link="left_hand_link" />
    <axis xyz="0 0 0" />
  </joint>
  <link name="left_hand_link">
    <inertial>
      <origin xyz="-0.00864938513630556 -0.00326690810975642 -0.0555569639549646" rpy="0 0 0" />
      <mass value="0.529944310592205" />
      <inertia ixx="0.000418985372588546" ixy="3.19284398454423E-06" ixz="-1.4224360742058E-05" iyy="0.000610580342357652" iyz="-2.24271246806261E-06" izz="0.000344172553571987" />
    </inertial>
    <visual>
      <origin xyz="0 0 0" rpy="0 0 0" />
      <geometry>
        <mesh filename="./meshes/left_hand_link.STL" />
      </geometry>
      <material name="">
        <color rgba="0.792156862745098 0.819607843137255 0.933333333333333 1" />
      </material>
    </visual>
    <collision>
      <origin xyz="0 0 0" rpy="0 0 0" />
      <geometry>
        <mesh filename="./meshes/left_hand_link.STL" />
      </geometry>
    </collision>
  </link>
  <link name="left_hand_ee_link">
    <inertial>
      <origin xyz="-1.69621793423315E-16 -7.89113564776902E-16 0" rpy="0 0 0" />
      <mass value="3.53429173528852E-08" />
      <inertia ixx="3.97607820219958E-14" ixy="2.1306062234609E-28" ixz="-6.0696092927852E-27" iyy="9.35114688295087E-14" iyz="2.40539124817171E-41" izz="9.35114688295086E-14" />
    </inertial>
    <visual>
      <origin xyz="0 0 0" rpy="0 0 0" />
      <geometry>
        <mesh filename="./meshes/left_hand_ee_link.STL" />
      </geometry>
      <material name="">
        <color rgba="0.698039215686274 0.698039215686274 0.698039215686274 1" />
      </material>
    </visual>
    <collision>
      <origin xyz="0 0 0" rpy="0 0 0" />
      <geometry>
        <mesh filename="./meshes/left_hand_ee_link.STL" />
      </geometry>
    </collision>
  </link>
  <joint name="left_hand_ee_joint" type="fixed">
    <origin xyz="0 0 -0.065" rpy="0 0 0" />
    <parent link="left_hand_link" />
    <child link="left_hand_ee_link" />
    <axis xyz="0 0 0" />
  </joint>
  <link name="left_hand_thumb_bend_link">
    <inertial>
      <origin xyz="0.0146951181783569 0.0010170558778431 0.000731323310503088" rpy="0 0 0" />
      <mass value="0.00988789386004912" />
      <inertia ixx="3.58716412139351E-07" ixy="-1.34105977059594E-08" ixz="-1.74484379968064E-08" iyy="2.30962520459155E-07" iyz="-2.48757133590212E-09" izz="2.11597841596506E-07" />
    </inertial>
    <visual>
      <origin xyz="0 0 0" rpy="0 0 0" />
      <geometry>
        <mesh filename="./meshes/left_hand_thumb_bend_link.STL" />
      </geometry>
      <material name="">
        <color rgba="0.615686274509804 0.643137254901961 0.674509803921569 1" />
      </material>
    </visual>
    <!-- <collision>
      <origin xyz="0 0 0" rpy="0 0 0" />
      <geometry>
        <mesh filename="./meshes/left_hand_thumb_bend_link.STL" />
      </geometry>
    </collision> -->
  </link>
  <joint name="left_hand_thumb_bend_joint" type="revolute">
    <origin xyz="0.0228 -0.0095 -0.0305" rpy="0 0 0" />
    <parent link="left_hand_link" />
    <child link="left_hand_thumb_bend_link" />
    <axis xyz="0 0 -1" />
    <limit lower="0" upper="1.83" effort="1.1" velocity="8.63" />
    <dynamics damping="1" friction="1" />
  </joint>
  <link name="left_hand_thumb_rota_link1">
    <inertial>
      <origin xyz="0.0287909625550219 -0.000242915671393474 0.00247391809705494" rpy="0 0 0" />
      <mass value="0.153155034156758" />
      <inertia ixx="2.78524098212563E-05" ixy="6.13812857719437E-07" ixz="-3.98638873366403E-07" iyy="2.82463477802506E-05" iyz="1.58606209561054E-07" izz="3.52591286553014E-05" />
    </inertial>
    <visual>
      <origin xyz="0 0 0" rpy="0 0 0" />
      <geometry>
        <mesh filename="./meshes/left_hand_thumb_rota_link1.STL" />
      </geometry>
      <material name="">
        <color rgba="1 1 1 1" />
      </material>
    </visual>
    <collision>
      <origin xyz="0 0 0" rpy="0 0 0" />
      <geometry>
        <mesh filename="./meshes/left_hand_thumb_rota_link1.STL" />
      </geometry>
    </collision>
  </link>
  <joint name="left_hand_thumb_rota_joint1" type="revolute">
    <origin xyz="0.0285986272129401 -0.00831765565268352 0.00177996188345445" rpy="-0.261799387798933 0 -0.0407002356493396" />
    <parent link="left_hand_thumb_bend_link" />
    <child link="left_hand_thumb_rota_link1" />
    <axis xyz="0 1 0" />
    <limit lower="-1.05" upper="1.57" effort="1.1" velocity="8.63" />
    <dynamics damping="1" friction="1" />
  </joint>
  <link name="left_hand_thumb_rota_link2">
    <inertial>
      <origin xyz="0.0246456234459003 2.69138722731738E-05 0.00357064212068477" rpy="0 0 0" />
      <mass value="0.0374005336514977" />
      <inertia ixx="3.92917396189104E-06" ixy="2.59293767017315E-09" ixz="6.44282025371109E-07" iyy="6.8488221061748E-06" iyz="6.06761479506332E-09" izz="7.99681697934097E-06" />
    </inertial>
    <visual>
      <origin xyz="0 0 0" rpy="0 0 0" />
      <geometry>
        <mesh filename="./meshes/left_hand_thumb_rota_link2.STL" />
      </geometry>
      <material name="">
        <color rgba="0.384313725490196 0.384313725490196 0.384313725490196 1" />
      </material>
    </visual>
    <collision>
      <origin xyz="0 0 0" rpy="0 0 0" />
      <geometry>
        <mesh filename="./meshes/left_hand_thumb_rota_link2.STL" />
      </geometry>
    </collision>
  </link>
  <joint name="left_hand_thumb_rota_joint2" type="revolute">
    <origin xyz="0.0552999999999999 0 0" rpy="0 0 0" />
    <parent link="left_hand_thumb_rota_link1" />
    <child link="left_hand_thumb_rota_link2" />
    <axis xyz="0 1 0" />
    <limit lower="-0.17" upper="1.83" effort="0.4" velocity="14.38" />
    <dynamics damping="1" friction="1" />
  </joint>
  <link name="left_hand_thumb_rota_tip">
    <inertial>
      <origin xyz="1.9728663147589E-13 8.24457366613296E-09 4.78089789979208E-15" rpy="0 0 0" />
      <mass value="3.53429173528852E-08" />
      <inertia ixx="9.35114688295088E-14" ixy="-4.24237404142101E-24" ixz="7.88860905221012E-31" iyy="3.97607820219958E-14" iyz="-1.27458623039275E-25" izz="9.35114688295087E-14" />
    </inertial>
    <visual>
      <origin xyz="0 0 0" rpy="0 0 0" />
      <geometry>
        <mesh filename="./meshes/left_hand_thumb_rota_tip.STL" />
      </geometry>
      <material name="">
        <color rgba="0.698039215686274 0.698039215686274 0.698039215686274 1" />
      </material>
    </visual>
    <collision>
      <origin xyz="0 0 0" rpy="0 0 0" />
      <geometry>
        <mesh filename="./meshes/left_hand_thumb_rota_tip.STL" />
      </geometry>
    </collision>
  </link>
  <joint name="left_hand_thumb_rota_joint3" type="fixed">
    <origin xyz="0.0504024555173588 0 0" rpy="0 0 0" />
    <parent link="left_hand_thumb_rota_link2" />
    <child link="left_hand_thumb_rota_tip" />
    <axis xyz="0 0 0" />
  </joint>
  <link name="left_hand_index_bend_link">
    <inertial>
      <origin xyz="-1.36538073638344E-05 -0.000296873462797107 0.0089696893565222" rpy="0 0 0" />
      <mass value="0.0678358392130179" />
      <inertia ixx="1.24579812319209E-05" ixy="-4.99427571322602E-10" ixz="-1.65009806493618E-08" iyy="1.16208585294442E-05" iyz="1.16944382314648E-06" izz="4.10931551097276E-06" />
    </inertial>
    <visual>
      <origin xyz="0 0 0" rpy="0 0 0" />
      <geometry>
        <mesh filename="./meshes/left_hand_index_bend_link.STL" />
      </geometry>
      <material name="">
        <color rgba="1 1 1 1" />
      </material>
    </visual>
    <!-- <collision>
      <origin xyz="0 0 0" rpy="0 0 0" />
      <geometry>
        <mesh filename="./meshes/left_hand_index_bend_link.STL" />
      </geometry>
    </collision> -->
  </link>
  <joint name="left_hand_index_bend_joint" type="revolute">
    <origin xyz="0.0265 -0.0065 -0.0899" rpy="0 0 0" />
    <parent link="left_hand_link" />
    <child link="left_hand_index_bend_link" />
    <axis xyz="0 -1 0" />
    <limit lower="-0.175" upper="0.175" effort="0.4" velocity="14.38" />
    <dynamics damping="1" friction="1" />
  </joint>
  <link name="left_hand_index_rota_link1">
    <inertial>
      <origin xyz="-1.33092584226023E-05 0.00117935465893214 -0.0314667592065465" rpy="0 0 0" />
      <mass value="0.0630023008144735" />
      <inertia ixx="1.2745607748276E-05" ixy="1.11697612170963E-08" ixz="-6.33464596137012E-08" iyy="1.13159526064873E-05" iyz="-7.4065747898706E-08" izz="3.96846238389722E-06" />
    </inertial>
    <visual>
      <origin xyz="0 0 0" rpy="0 0 0" />
      <geometry>
        <mesh filename="./meshes/left_hand_index_rota_link1.STL" />
      </geometry>
      <material name="">
        <color rgba="1 1 1 1" />
      </material>
    </visual>
    <collision>
      <origin xyz="0 0 0" rpy="0 0 0" />
      <geometry>
        <mesh filename="./meshes/left_hand_index_rota_link1.STL" />
      </geometry>
    </collision>
  </link>
  <joint name="left_hand_index_joint1" type="revolute">
    <origin xyz="0 0 -0.0178" rpy="0 0 0" />
    <parent link="left_hand_index_bend_link" />
    <child link="left_hand_index_rota_link1" />
    <axis xyz="-1 0 0" />
    <limit lower="0" upper="1.92" effort="1.1" velocity="8.63" />
    <dynamics damping="1" friction="1" />
  </joint>
  <link name="left_hand_index_rota_link2">
    <inertial>
      <origin xyz="0.000105984925146081 0.000552347223597082 -0.0269533774742111" rpy="0 0 0" />
      <mass value="0.017978306795458" />
      <inertia ixx="1.57447652114977E-06" ixy="2.76146301079716E-09" ixz="-2.28756514380631E-08" iyy="1.41206918399455E-06" iyz="-7.17000486348478E-09" izz="9.25906469018155E-07" />
    </inertial>
    <visual>
      <origin xyz="0 0 0" rpy="0 0 0" />
      <geometry>
        <mesh filename="./meshes/left_hand_index_rota_link2.STL" />
      </geometry>
      <material name="">
        <color rgba="0.866666666666667 0.866666666666667 0.890196078431372 1" />
      </material>
    </visual>
    <collision>
      <origin xyz="0 0 0" rpy="0 0 0" />
      <geometry>
        <mesh filename="./meshes/left_hand_index_rota_link2.STL" />
      </geometry>
    </collision>
  </link>
  <joint name="left_hand_index_joint2" type="revolute">
    <origin xyz="0 0 -0.0558" rpy="0 0 0" />
    <parent link="left_hand_index_rota_link1" />
    <child link="left_hand_index_rota_link2" />
    <axis xyz="-1 0 0" />
    <limit lower="0" upper="1.92" effort="0.4" velocity="14.38" />
    <dynamics damping="1" friction="1" />
  </joint>
  <link name="left_hand_index_rota_tip">
    <inertial>
      <origin xyz="-9.29811783123569E-16 -2.63938176869871E-15 -8.32667268468867E-17" rpy="0 0 0" />
      <mass value="3.53429173528852E-08" />
      <inertia ixx="3.97607820219958E-14" ixy="2.0659827381052E-28" ixz="2.52777196678214E-29" iyy="9.35114688295087E-14" iyz="-1.34524652575182E-43" izz="9.35114688295087E-14" />
    </inertial>
    <visual>
      <origin xyz="0 0 0" rpy="0 0 0" />
      <geometry>
        <mesh filename="./meshes/left_hand_index_rota_tip.STL" />
      </geometry>
      <material name="">
        <color rgba="0.698039215686274 0.698039215686274 0.698039215686274 1" />
      </material>
    </visual>
    <collision>
      <origin xyz="0 0 0" rpy="0 0 0" />
      <geometry>
        <mesh filename="./meshes/left_hand_index_rota_tip.STL" />
      </geometry>
    </collision>
  </link>
  <joint name="left_hand_index_rota_joint3" type="fixed">
    <origin xyz="0 0 -0.0424999999999999" rpy="0 0 0" />
    <parent link="left_hand_index_rota_link2" />
    <child link="left_hand_index_rota_tip" />
    <axis xyz="0 0 0" />
  </joint>
  <link name="left_hand_mid_link1">
    <inertial>
      <origin xyz="-1.33093186277912E-05 0.00117935480050193 -0.0314667591863722" rpy="0 0 0" />
      <mass value="0.0630023022013301" />
      <inertia ixx="1.27456081957855E-05" ixy="1.11697922297878E-08" ixz="-6.33466790814787E-08" iyy="1.13159531276305E-05" iyz="-7.40657415672241E-08" izz="3.96846251967624E-06" />
    </inertial>
    <visual>
      <origin xyz="0 0 0" rpy="0 0 0" />
      <geometry>
        <mesh filename="./meshes/left_hand_mid_link1.STL" />
      </geometry>
      <material name="">
        <color rgba="1 1 1 1" />
      </material>
    </visual>
    <collision>
      <origin xyz="0 0 0" rpy="0 0 0" />
      <geometry>
        <mesh filename="./meshes/left_hand_mid_link1.STL" />
      </geometry>
    </collision>
  </link>
  <joint name="left_hand_mid_joint1" type="revolute">
    <origin xyz="0.004 -0.0065 -0.1082" rpy="0 0 0" />
    <parent link="left_hand_link" />
    <child link="left_hand_mid_link1" />
    <axis xyz="-1 0 0" />
    <limit lower="0" upper="1.92" effort="1.1" velocity="8.63" />
    <dynamics damping="1" friction="1" />
  </joint>
  <link name="left_hand_mid_link2">
    <inertial>
      <origin xyz="0.000105984928455458 0.000552347222436347 -0.0269533774807861" rpy="0 0 0" />
      <mass value="0.0179783068080897" />
      <inertia ixx="1.57447652237869E-06" ixy="2.76146317048659E-09" ixz="-2.28756508518856E-08" iyy="1.41206918545466E-06" iyz="-7.17000503278344E-09" izz="9.25906469321219E-07" />
    </inertial>
    <visual>
      <origin xyz="0 0 0" rpy="0 0 0" />
      <geometry>
        <mesh filename="./meshes/left_hand_mid_link2.STL" />
      </geometry>
      <material name="">
        <color rgba="0.866666666666667 0.866666666666667 0.890196078431372 1" />
      </material>
    </visual>
    <collision>
      <origin xyz="0 0 0" rpy="0 0 0" />
      <geometry>
        <mesh filename="./meshes/left_hand_mid_link2.STL" />
      </geometry>
    </collision>
  </link>
  <joint name="left_hand_mid_joint2" type="revolute">
    <origin xyz="0 0 -0.0558" rpy="0 0 0" />
    <parent link="left_hand_mid_link1" />
    <child link="left_hand_mid_link2" />
    <axis xyz="-1 0 0" />
    <limit lower="0" upper="1.92" effort="0.4" velocity="14.38" />
    <dynamics damping="1" friction="1" />
  </joint>
  <link name="left_hand_mid_tip">
    <inertial>
      <origin xyz="-5.69856661858381E-16 2.09944908680093E-14 -2.4980018054066E-16" rpy="0 0 0" />
      <mass value="3.53429173528852E-08" />
      <inertia ixx="3.97607820219958E-14" ixy="2.08752389989043E-28" ixz="2.52777196678215E-29" iyy="9.35114688295087E-14" iyz="-1.79366203433577E-43" izz="9.35114688295086E-14" />
    </inertial>
    <visual>
      <origin xyz="0 0 0" rpy="0 0 0" />
      <geometry>
        <mesh filename="./meshes/left_hand_mid_tip.STL" />
      </geometry>
      <material name="">
        <color rgba="0.698039215686274 0.698039215686274 0.698039215686274 1" />
      </material>
    </visual>
    <collision>
      <origin xyz="0 0 0" rpy="0 0 0" />
      <geometry>
        <mesh filename="./meshes/left_hand_mid_tip.STL" />
      </geometry>
    </collision>
  </link>
  <joint name="left_hand_mid_joint3" type="fixed">
    <origin xyz="0 0 -0.042500000000001" rpy="0 0 0" />
    <parent link="left_hand_mid_link2" />
    <child link="left_hand_mid_tip" />
    <axis xyz="0 0 0" />
  </joint>
  <link name="left_hand_ring_link1">
    <inertial>
      <origin xyz="-1.33096483662491E-05 0.00117935450409436 -0.0314667596675611" rpy="0 0 0" />
      <mass value="0.0630023002480442" />
      <inertia ixx="1.27456074975177E-05" ixy="1.11699975266944E-08" ixz="-6.33465151788219E-08" iyy="1.13159525096134E-05" iyz="-7.40654037517664E-08" izz="3.96846226001982E-06" />
    </inertial>
    <visual>
      <origin xyz="0 0 0" rpy="0 0 0" />
      <geometry>
        <mesh filename="./meshes/left_hand_ring_link1.STL" />
      </geometry>
      <material name="">
        <color rgba="1 1 1 1" />
      </material>
    </visual>
    <collision>
      <origin xyz="0 0 0" rpy="0 0 0" />
      <geometry>
        <mesh filename="./meshes/left_hand_ring_link1.STL" />
      </geometry>
    </collision>
  </link>
  <joint name="left_hand_ring_joint1" type="revolute">
    <origin xyz="-0.016 -0.0065 -0.1052" rpy="0 0 0" />
    <parent link="left_hand_link" />
    <child link="left_hand_ring_link1" />
    <axis xyz="-1 0 0" />
    <limit lower="0" upper="1.92" effort="1.1" velocity="8.63" />
    <dynamics damping="1" friction="1" />
  </joint>
  <link name="left_hand_ring_link2">
    <inertial>
      <origin xyz="0.000105984925353953 0.00055234722341907 -0.0269533774746112" rpy="0 0 0" />
      <mass value="0.0179783067963059" />
      <inertia ixx="1.57447652123335E-06" ixy="2.76146302722388E-09" ixz="-2.2875651400635E-08" iyy="1.41206918407907E-06" iyz="-7.17000489119851E-09" izz="9.25906469042038E-07" />
    </inertial>
    <visual>
      <origin xyz="0 0 0" rpy="0 0 0" />
      <geometry>
        <mesh filename="./meshes/left_hand_ring_link2.STL" />
      </geometry>
      <material name="">
        <color rgba="0.866666666666667 0.866666666666667 0.890196078431372 1" />
      </material>
    </visual>
    <collision>
      <origin xyz="0 0 0" rpy="0 0 0" />
      <geometry>
        <mesh filename="./meshes/left_hand_ring_link2.STL" />
      </geometry>
    </collision>
  </link>
  <joint name="left_hand_ring_joint2" type="revolute">
    <origin xyz="0 0 -0.0558" rpy="0 0 0" />
    <parent link="left_hand_ring_link1" />
    <child link="left_hand_ring_link2" />
    <axis xyz="-1 0 0" />
    <limit lower="0" upper="1.92" effort="0.4" velocity="14.38" />
    <dynamics damping="1" friction="1" />
  </joint>
  <link name="left_hand_ring_tip">
    <inertial>
      <origin xyz="-5.41233724504764E-16 -5.26488574958961E-16 -2.22044604925031E-16" rpy="0 0 0" />
      <mass value="3.53429173528852E-08" />
      <inertia ixx="3.97607820219958E-14" ixy="2.08752389989043E-28" ixz="2.52777196678215E-29" iyy="9.35114688295087E-14" iyz="-1.79366203433577E-43" izz="9.35114688295087E-14" />
    </inertial>
    <visual>
      <origin xyz="0 0 0" rpy="0 0 0" />
      <geometry>
        <mesh filename="./meshes/left_hand_ring_tip.STL" />
      </geometry>
      <material name="">
        <color rgba="0.698039215686274 0.698039215686274 0.698039215686274 1" />
      </material>
    </visual>
    <collision>
      <origin xyz="0 0 0" rpy="0 0 0" />
      <geometry>
        <mesh filename="./meshes/left_hand_ring_tip.STL" />
      </geometry>
    </collision>
  </link>
  <joint name="left_hand_ring_joint3" type="fixed">
    <origin xyz="0 0 -0.0424999999999995" rpy="0 0 0" />
    <parent link="left_hand_ring_link2" />
    <child link="left_hand_ring_tip" />
    <axis xyz="0 0 0" />
  </joint>
  <link name="left_hand_pinky_link1">
    <inertial>
      <origin xyz="-1.33096859500845E-05 0.00117935408946108 -0.0314667601427276" rpy="0 0 0" />
      <mass value="0.0630022982822898" />
      <inertia ixx="1.27456068030847E-05" ixy="1.11700454508605E-08" ixz="-6.33463944280954E-08" iyy="1.13159521295488E-05" iyz="-7.40650389817798E-08" izz="3.9684619246592E-06" />
    </inertial>
    <visual>
      <origin xyz="0 0 0" rpy="0 0 0" />
      <geometry>
        <mesh filename="./meshes/left_hand_pinky_link1.STL" />
      </geometry>
      <material name="">
        <color rgba="1 1 1 1" />
      </material>
    </visual>
    <collision>
      <origin xyz="0 0 0" rpy="0 0 0" />
      <geometry>
        <mesh filename="./meshes/left_hand_pinky_link1.STL" />
      </geometry>
    </collision>
  </link>
  <joint name="left_hand_pinky_joint1" type="revolute">
    <origin xyz="-0.036 -0.0065 -0.1022" rpy="0 0 0" />
    <parent link="left_hand_link" />
    <child link="left_hand_pinky_link1" />
    <axis xyz="-1 0 0" />
    <limit lower="0" upper="1.92" effort="1.1" velocity="8.63" />
    <dynamics damping="1" friction="1" />
  </joint>
  <link name="left_hand_pinky_link2">
    <inertial>
      <origin xyz="0.000105984925057048 0.000552347223524425 -0.0269533774743773" rpy="0 0 0" />
      <mass value="0.0179783067958151" />
      <inertia ixx="1.57447652118483E-06" ixy="2.76146300285892E-09" ixz="-2.28756514521984E-08" iyy="1.41206918402886E-06" iyz="-7.1700048779914E-09" izz="9.25906469033028E-07" />
    </inertial>
    <visual>
      <origin xyz="0 0 0" rpy="0 0 0" />
      <geometry>
        <mesh filename="./meshes/left_hand_pinky_link2.STL" />
      </geometry>
      <material name="">
        <color rgba="0.866666666666667 0.866666666666667 0.890196078431372 1" />
      </material>
    </visual>
    <collision>
      <origin xyz="0 0 0" rpy="0 0 0" />
      <geometry>
        <mesh filename="./meshes/left_hand_pinky_link2.STL" />
      </geometry>
    </collision>
  </link>
  <joint name="left_hand_pinky_joint2" type="revolute">
    <origin xyz="0 0 -0.0558" rpy="0 0 0" />
    <parent link="left_hand_pinky_link1" />
    <child link="left_hand_pinky_link2" />
    <axis xyz="-1 0 0" />
    <limit lower="0" upper="1.92" effort="0.4" velocity="14.38" />
    <dynamics damping="1" friction="1" />
  </joint>
  <link name="left_hand_pinky_tip">
    <inertial>
      <origin xyz="-5.34294830600857E-16 -3.06005221162309E-15 -1.38777878078145E-16" rpy="0 0 0" />
      <mass value="3.53429173528851E-08" />
      <inertia ixx="3.97607820219958E-14" ixy="2.08752389989043E-28" ixz="2.52777196678213E-29" iyy="9.35114688295085E-14" iyz="-1.79366203433577E-43" izz="9.35114688295085E-14" />
    </inertial>
    <visual>
      <origin xyz="0 0 0" rpy="0 0 0" />
      <geometry>
        <mesh filename="./meshes/left_hand_pinky_tip.STL" />
      </geometry>
      <material name="">
        <color rgba="0.698039215686274 0.698039215686274 0.698039215686274 1" />
      </material>
    </visual>
    <collision>
      <origin xyz="0 0 0" rpy="0 0 0" />
      <geometry>
        <mesh filename="./meshes/left_hand_pinky_tip.STL" />
      </geometry>
    </collision>
  </link>
  <joint name="left_hand_pinky_joint3" type="fixed">
    <origin xyz="0 0 -0.0425" rpy="0 0 0" />
    <parent link="left_hand_pinky_link2" />
    <child link="left_hand_pinky_tip" />
    <axis xyz="0 0 0" />
  </joint>
</robot>