<mujoco model="xhand_right">
  <compiler angle="radian" meshdir="./meshes/"/>

  <asset>
    <mesh name="right_hand_link" file="right_hand_link.STL"/>
    <mesh name="right_hand_thumb_bend_link" file="right_hand_thumb_bend_link.STL"/>
    <mesh name="right_hand_thumb_rota_link1" file="right_hand_thumb_rota_link1.STL"/>
    <mesh name="right_hand_thumb_rota_link2" file="right_hand_thumb_rota_link2.STL"/>
    <mesh name="right_hand_thumb_rota_tip" file="right_hand_thumb_rota_tip.STL"/>
    <mesh name="right_hand_index_bend_link" file="right_hand_index_bend_link.STL"/>
    <mesh name="right_hand_index_rota_link1" file="right_hand_index_rota_link1.STL"/>
    <mesh name="right_hand_index_rota_link2" file="right_hand_index_rota_link2.STL"/>
    <mesh name="right_hand_index_rota_tip" file="right_hand_index_rota_tip.STL"/>
    <mesh name="right_hand_mid_link1" file="right_hand_mid_link1.STL"/>
    <mesh name="right_hand_mid_link2" file="right_hand_mid_link2.STL"/>
    <mesh name="right_hand_mid_tip" file="right_hand_mid_tip.STL"/>
    <mesh name="right_hand_ring_link1" file="right_hand_ring_link1.STL"/>
    <mesh name="right_hand_ring_link2" file="right_hand_ring_link2.STL"/>
    <mesh name="right_hand_ring_tip" file="right_hand_ring_tip.STL"/>
    <mesh name="right_hand_pinky_link1" file="right_hand_pinky_link1.STL"/>
    <mesh name="right_hand_pinky_link2" file="right_hand_pinky_link2.STL"/>
    <mesh name="right_hand_pinky_tip" file="right_hand_pinky_tip.STL"/>
    <mesh name="right_hand_ee_link" file="right_hand_ee_link.STL"/>
  </asset>

  <worldbody>
    <geom type="mesh" contype="0" conaffinity="0" group="1" density="0" rgba="0.792157 0.819608 0.933333 1" mesh="right_hand_link"/>
    <geom type="mesh" rgba="0.792157 0.819608 0.933333 1" mesh="right_hand_link"/>
    <geom pos="0 0 -0.065" quat="1 0 0 0" type="mesh" contype="0" conaffinity="0" group="1" density="0" rgba="0.698039 0.698039 0.698039 1" mesh="right_hand_ee_link"/>
    <geom pos="0 0 -0.065" quat="1 0 0 0" type="mesh" rgba="0.698039 0.698039 0.698039 1" mesh="right_hand_ee_link"/>
    <body name="right_hand_thumb_bend_link" pos="0.0228 0.0095 -0.0305">
      <inertial pos="0.014728 -0.000946298 9.99381e-05" quat="0.977428 0.193001 0.0799378 0.0315505" mass="0.00988485" diaginertia="3.48585e-07 2.18237e-07 2.08972e-07"/>
      <joint name="right_hand_thumb_bend_joint" pos="0 0 0" axis="0 0 1" range="0 1.83" actuatorfrcrange="-1.1 1.1" damping="1" frictionloss="1"/>
      <geom type="mesh" contype="0" conaffinity="0" group="1" density="0" rgba="0.615686 0.643137 0.67451 1" mesh="right_hand_thumb_bend_link"/>
      <body name="right_hand_thumb_rota_link1" pos="0.028599 0.0083177 0.00178" quat="0.99124 0.130499 0.00265603 0.0201745">
        <inertial pos="0.0287861 0.000236855 0.00247774" quat="-0.216796 0.653638 0.216779 0.691928" mass="0.153227" diaginertia="3.53026e-05 2.87127e-05 2.73927e-05"/>
        <joint name="right_hand_thumb_rota_joint1" pos="0 0 0" axis="0 1 0" range="-1.05 1.57" actuatorfrcrange="-1.1 1.1" damping="1" frictionloss="1"/>
        <geom type="mesh" contype="0" conaffinity="0" group="1" density="0" rgba="1 1 1 1" mesh="right_hand_thumb_rota_link1"/>
        <geom type="mesh" rgba="1 1 1 1" mesh="right_hand_thumb_rota_link1"/>
        <body name="right_hand_thumb_rota_link2" pos="0.0553 0 0">
          <inertial pos="0.0246456 -2.89183e-05 0.00357057" quat="-0.00186069 0.759204 -0.00155693 0.650849" mass="0.0374009" diaginertia="8.09652e-06 6.84887e-06 3.82962e-06"/>
          <joint name="right_hand_thumb_rota_joint2" pos="0 0 0" axis="0 1 0" range="-0.175 1.83" actuatorfrcrange="-0.4 0.4" damping="1" frictionloss="1"/>
          <geom type="mesh" contype="0" conaffinity="0" group="1" density="0" rgba="0.384314 0.384314 0.384314 1" mesh="right_hand_thumb_rota_link2"/>
          <geom type="mesh" rgba="0.384314 0.384314 0.384314 1" mesh="right_hand_thumb_rota_link2"/>
          <geom pos="0.0504025 0 0" quat="1 0 0 0" type="mesh" contype="0" conaffinity="0" group="1" density="0" rgba="0.698039 0.698039 0.698039 1" mesh="right_hand_thumb_rota_tip"/>
          <geom pos="0.0504025 0 0" quat="1 0 0 0" type="mesh" rgba="0.698039 0.698039 0.698039 1" mesh="right_hand_thumb_rota_tip"/>
        </body>
      </body>
    </body>
    <body name="right_hand_index_bend_link" pos="0.0265 0.0065 -0.0899">
      <inertial pos="1.36538e-05 0.000296873 0.00896969" quat="0.997151 -0.0753904 -0.00111959 -0.00217774" mass="0.0678358" diaginertia="1.2458e-05 1.17987e-05 3.93143e-06"/>
      <joint name="right_hand_index_bend_joint" pos="0 0 0" axis="0 -1 0" range="-0.175 0.175" actuatorfrcrange="-0.4 0.4" damping="1" frictionloss="1"/>
      <geom type="mesh" contype="0" conaffinity="0" group="1" density="0" rgba="1 1 1 1" mesh="right_hand_index_bend_link"/>
      <body name="right_hand_index_rota_link1" pos="0 0 -0.0178">
        <inertial pos="1.33096e-05 -0.00117935 -0.0314668" quat="0.999972 0.00501873 -0.0036222 0.00411172" mass="0.0630023" diaginertia="1.27462e-05 1.13166e-05 3.96726e-06"/>
        <joint name="right_hand_index_joint1" pos="0 0 0" axis="1 0 0" range="0 1.92" actuatorfrcrange="-1.1 1.1" damping="1" frictionloss="1"/>
        <geom type="mesh" contype="0" conaffinity="0" group="1" density="0" rgba="1 1 1 1" mesh="right_hand_index_rota_link1"/>
        <geom type="mesh" rgba="1 1 1 1" mesh="right_hand_index_rota_link1"/>
        <body name="right_hand_index_rota_link2" pos="0 0 -0.0558">
          <inertial pos="-0.000105985 -0.000552346 -0.0269534" quat="0.999776 0.00709054 -0.0176373 0.00935454" mass="0.0179783" diaginertia="1.57535e-06 1.41212e-06 9.24998e-07"/>
          <joint name="right_hand_index_joint2" pos="0 0 0" axis="1 0 0" range="0 1.92" actuatorfrcrange="-0.4 0.4" damping="1" frictionloss="1"/>
          <geom type="mesh" contype="0" conaffinity="0" group="1" density="0" rgba="0.866667 0.866667 0.890196 1" mesh="right_hand_index_rota_link2"/>
          <geom type="mesh" rgba="0.866667 0.866667 0.890196 1" mesh="right_hand_index_rota_link2"/>
          <geom pos="0 0 -0.0425" quat="1 0 0 0" type="mesh" contype="0" conaffinity="0" group="1" density="0" rgba="0.698039 0.698039 0.698039 1" mesh="right_hand_index_rota_tip"/>
          <geom pos="0 0 -0.0425" quat="1 0 0 0" type="mesh" rgba="0.698039 0.698039 0.698039 1" mesh="right_hand_index_rota_tip"/>
        </body>
      </body>
    </body>
    <body name="right_hand_mid_link1" pos="0.004 0.0065 -0.1082">
      <inertial pos="1.33096e-05 -0.00117935 -0.0314668" quat="0.999972 0.00501871 -0.00362219 0.00411173" mass="0.0630023" diaginertia="1.27462e-05 1.13166e-05 3.96726e-06"/>
      <joint name="right_hand_mid_joint1" pos="0 0 0" axis="1 0 0" range="0 1.92" actuatorfrcrange="-1.1 1.1" damping="1" frictionloss="1"/>
      <geom type="mesh" contype="0" conaffinity="0" group="1" density="0" rgba="1 1 1 1" mesh="right_hand_mid_link1"/>
      <geom type="mesh" rgba="1 1 1 1" mesh="right_hand_mid_link1"/>
      <body name="right_hand_mid_link2" pos="0 0 -0.0558">
        <inertial pos="-0.000105985 -0.000552346 -0.0269534" quat="0.999776 0.00709054 -0.0176373 0.00935454" mass="0.0179783" diaginertia="1.57535e-06 1.41212e-06 9.24998e-07"/>
        <joint name="right_hand_mid_joint2" pos="0 0 0" axis="1 0 0" range="0 1.94" actuatorfrcrange="-0.4 0.4" damping="1" frictionloss="1"/>
        <geom type="mesh" contype="0" conaffinity="0" group="1" density="0" rgba="0.866667 0.866667 0.890196 1" mesh="right_hand_mid_link2"/>
        <geom type="mesh" rgba="0.866667 0.866667 0.890196 1" mesh="right_hand_mid_link2"/>
        <geom pos="0 0 -0.0425" quat="1 0 0 0" type="mesh" contype="0" conaffinity="0" group="1" density="0" rgba="0.698039 0.698039 0.698039 1" mesh="right_hand_mid_tip"/>
        <geom pos="0 0 -0.0425" quat="1 0 0 0" type="mesh" rgba="0.698039 0.698039 0.698039 1" mesh="right_hand_mid_tip"/>
      </body>
    </body>
    <body name="right_hand_ring_link1" pos="-0.016 0.0065 -0.1052">
      <inertial pos="1.33095e-05 -0.00117936 -0.0314668" quat="0.999972 0.00501876 -0.0036222 0.00411169" mass="0.0630023" diaginertia="1.27462e-05 1.13166e-05 3.96726e-06"/>
      <joint name="right_hand_ring_joint1" pos="0 0 0" axis="1 0 0" range="0 1.92" actuatorfrcrange="-1.1 1.1" damping="1" frictionloss="1"/>
      <geom type="mesh" contype="0" conaffinity="0" group="1" density="0" rgba="1 1 1 1" mesh="right_hand_ring_link1"/>
      <geom type="mesh" rgba="1 1 1 1" mesh="right_hand_ring_link1"/>
      <body name="right_hand_ring_link2" pos="0 0 -0.0558">
        <inertial pos="-0.000105984 -0.000552346 -0.0269534" quat="0.999776 0.00708969 -0.017637 0.00935397" mass="0.0179783" diaginertia="1.57535e-06 1.41212e-06 9.24998e-07"/>
        <joint name="right_hand_ring_joint2" pos="0 0 0" axis="1 0 0" range="0 1.92" actuatorfrcrange="-0.4 0.4" damping="1" frictionloss="1"/>
        <geom type="mesh" contype="0" conaffinity="0" group="1" density="0" rgba="0.866667 0.866667 0.890196 1" mesh="right_hand_ring_link2"/>
        <geom type="mesh" rgba="0.866667 0.866667 0.890196 1" mesh="right_hand_ring_link2"/>
        <geom pos="0 0 -0.0425" quat="1 0 0 0" type="mesh" contype="0" conaffinity="0" group="1" density="0" rgba="0.698039 0.698039 0.698039 1" mesh="right_hand_ring_tip"/>
        <geom pos="0 0 -0.0425" quat="1 0 0 0" type="mesh" rgba="0.698039 0.698039 0.698039 1" mesh="right_hand_ring_tip"/>
      </body>
    </body>
    <body name="right_hand_pinky_link1" pos="-0.036 0.0065 -0.1022">
      <inertial pos="1.33097e-05 -0.00117935 -0.0314668" quat="0.999972 0.00501874 -0.00362219 0.00411174" mass="0.0630023" diaginertia="1.27462e-05 1.13166e-05 3.96726e-06"/>
      <joint name="right_hand_pinky_joint1" pos="0 0 0" axis="1 0 0" range="0 1.92" actuatorfrcrange="-1.1 1.1" damping="1" frictionloss="1"/>
      <geom type="mesh" contype="0" conaffinity="0" group="1" density="0" rgba="1 1 1 1" mesh="right_hand_pinky_link1"/>
      <geom type="mesh" rgba="1 1 1 1" mesh="right_hand_pinky_link1"/>
      <body name="right_hand_pinky_link2" pos="0 0 -0.0558">
        <inertial pos="-0.000105985 -0.000552346 -0.0269534" quat="0.999776 0.00709054 -0.0176373 0.00935453" mass="0.0179783" diaginertia="1.57535e-06 1.41212e-06 9.24998e-07"/>
        <joint name="right_hand_pinky_joint2" pos="0 0 0" axis="1 0 0" range="0 1.92" actuatorfrcrange="-0.4 0.4" damping="1" frictionloss="1"/>
        <geom type="mesh" contype="0" conaffinity="0" group="1" density="0" rgba="0.866667 0.866667 0.890196 1" mesh="right_hand_pinky_link2"/>
        <geom type="mesh" rgba="0.866667 0.866667 0.890196 1" mesh="right_hand_pinky_link2"/>
        <geom pos="0 0 -0.0425" quat="1 0 0 0" type="mesh" contype="0" conaffinity="0" group="1" density="0" rgba="0.698039 0.698039 0.698039 1" mesh="right_hand_pinky_tip"/>
        <geom pos="0 0 -0.0425" quat="1 0 0 0" type="mesh" rgba="0.698039 0.698039 0.698039 1" mesh="right_hand_pinky_tip"/>
      </body>
    </body>
  </worldbody>
</mujoco>
