<?xml version="1.0" encoding="utf-8"?>
<!-- This URDF was automatically created by SolidWorks to URDF Exporter! Originally created by Stephen Brawner (brawner@gmail.com) 
     Commit Version: 1.6.0-4-g7f85cfe  Build Version: 1.6.7995.38578
     For more information, please see http://wiki.ros.org/sw_urdf_exporter -->
<robot name="xhand_right">
  <mujoco>
    <compiler meshdir="./meshes/" balanceinertia="true" discardvisual="false" />
  </mujoco>
  <link name="base_link">
  </link>
  <joint name="base_link_joint" type="fixed">
    <origin xyz="0 0 0.0" rpy="0 0 0" />
    <parent link="base_link" />
    <child link="right_hand_link" />
    <axis xyz="0 0 0" />
  </joint>
  <link name="right_hand_link">
    <inertial>
      <origin xyz="-0.00864974314300298 0.00326565882630545 -0.0555553270680597" rpy="0 0 0" />
      <mass value="0.529993400990084" />
      <inertia ixx="0.000418999657578924" ixy="-3.20486078360989E-06" ixz="-1.42467216933388E-05" iyy="0.000610637316693744" iyz="2.25090396270209E-06" izz="0.000344223764949739" />
    </inertial>
    <visual>
      <origin xyz="0 0 0" rpy="0 0 0" />
      <geometry>
        <mesh filename="./meshes/right_hand_link.STL" />
      </geometry>
      <material name="">
        <color rgba="0.792156862745098 0.819607843137255 0.933333333333333 1" />
      </material>
    </visual>
    <collision>
      <origin xyz="0 0 0" rpy="0 0 0" />
      <geometry>
        <mesh filename="./meshes/right_hand_link.STL" />
      </geometry>
    </collision>
  </link>
  <link name="right_hand_thumb_bend_link">
    <inertial>
      <origin xyz="0.0147280320458096 -0.000946297828788122 9.99380716844647E-05" rpy="0 0 0" />
      <mass value="0.0098848519917835" />
      <inertia ixx="3.44499507557935E-07" ixy="1.24641683760561E-08" ixz="-1.99285126830707E-08" iyy="2.18069247024708E-07" iyz="1.40954007652469E-09" izz="2.13225056396345E-07" />
    </inertial>
    <visual>
      <origin xyz="0 0 0" rpy="0 0 0" />
      <geometry>
        <mesh filename="./meshes/right_hand_thumb_bend_link.STL" />
      </geometry>
      <material name="">
        <color rgba="0.615686274509804 0.643137254901961 0.674509803921569 1" />
      </material>
    </visual>
    <!-- <collision>
      <origin xyz="0 0 0" rpy="0 0 0" />
      <geometry>
        <mesh filename="./meshes/right_hand_thumb_bend_link.STL" />
      </geometry>
    </collision> -->
  </link>
  <joint name="right_hand_thumb_bend_joint" type="revolute">
    <origin xyz="0.0228 0.0095 -0.0305" rpy="0 0 0" />
    <parent link="right_hand_link" />
    <child link="right_hand_thumb_bend_link" />
    <axis xyz="0 0 1" />
    <limit lower="0" upper="1.83" effort="1.1" velocity="8.63" />
    <dynamics damping="1" friction="1" />
  </joint>
  <link name="right_hand_thumb_rota_link1">
    <inertial>
      <origin xyz="0.028786112807607 0.000236855243653546 0.00247774188906292" rpy="0 0 0" />
      <mass value="0.153227150322195" />
      <inertia ixx="2.78629858227337E-05" ixy="-6.18512652464855E-07" ixz="-3.94101233177151E-07" iyy="2.82652402505648E-05" iyz="-1.49066720299264E-07" izz="3.52797384287539E-05" />
    </inertial>
    <visual>
      <origin xyz="0 0 0" rpy="0 0 0" />
      <geometry>
        <mesh filename="./meshes/right_hand_thumb_rota_link1.STL" />
      </geometry>
      <material name="">
        <color rgba="1 1 1 1" />
      </material>
    </visual>
    <collision>
      <origin xyz="0 0 0" rpy="0 0 0" />
      <geometry>
        <mesh filename="./meshes/right_hand_thumb_rota_link1.STL" />
      </geometry>
    </collision>
  </link>
  <joint name="right_hand_thumb_rota_joint1" type="revolute">
    <origin xyz="0.028599 0.0083177 0.00178" rpy="0.2618 0 0.0407" />
    <parent link="right_hand_thumb_bend_link" />
    <child link="right_hand_thumb_rota_link1" />
    <axis xyz="0 1 0" />
    <limit lower="-1.05" upper="1.57" effort="1.1" velocity="8.63" />
    <dynamics damping="1" friction="1" />
  </joint>
  <link name="right_hand_thumb_rota_link2">
    <inertial>
      <origin xyz="0.0246455701534738 -2.89183235859802E-05 0.00357056960005082" rpy="0 0 0" />
      <mass value="0.0374008322024407" />
      <inertia ixx="3.92922226445762E-06" ixy="-3.29527472059864E-09" ixz="6.44262388952476E-07" iyy="6.84887294284889E-06" iyz="-5.53284390524763E-09" izz="7.99686550560469E-06" />
    </inertial>
    <visual>
      <origin xyz="0 0 0" rpy="0 0 0" />
      <geometry>
        <mesh filename="./meshes/right_hand_thumb_rota_link2.STL" />
      </geometry>
      <material name="">
        <color rgba="0.384313725490196 0.384313725490196 0.384313725490196 1" />
      </material>
    </visual>
    <collision>
      <origin xyz="0 0 0" rpy="0 0 0" />
      <geometry>
        <mesh filename="./meshes/right_hand_thumb_rota_link2.STL" />
      </geometry>
    </collision>
  </link>
  <joint name="right_hand_thumb_rota_joint2" type="revolute">
    <origin xyz="0.0553 0 0" rpy="0 0 0" />
    <parent link="right_hand_thumb_rota_link1" />
    <child link="right_hand_thumb_rota_link2" />
    <axis xyz="0 1 0" />
    <limit lower="-0.175" upper="1.83" effort="0.4" velocity="14.38" />
    <dynamics damping="1" friction="1" />
  </joint>
  <link name="right_hand_thumb_rota_tip">
    <inertial>
      <origin xyz="8.28680679632043E-10 -8.24456677060714E-09 2.42861286636753E-16" rpy="0 0 0" />
      <mass value="3.53429173528852E-08" />
      <inertia ixx="9.35114688295028E-14" ixy="1.78168639300598E-20" ixz="1.38050658413677E-30" iyy="3.97607820220017E-14" iyz="-8.20415341429852E-29" izz="9.35114688295087E-14" />
    </inertial>
    <visual>
      <origin xyz="0 0 0" rpy="0 0 0" />
      <geometry>
        <mesh filename="./meshes/right_hand_thumb_rota_tip.STL" />
      </geometry>
      <material name="">
        <color rgba="0.698039215686274 0.698039215686274 0.698039215686274 1" />
      </material>
    </visual>
    <collision>
      <origin xyz="0 0 0" rpy="0 0 0" />
      <geometry>
        <mesh filename="./meshes/right_hand_thumb_rota_tip.STL" />
      </geometry>
    </collision>
  </link>
  <joint name="right_hand_thumb_rota_joint3" type="fixed">
    <origin xyz="0.0504024546888782 0 0" rpy="0 0 0" />
    <parent link="right_hand_thumb_rota_link2" />
    <child link="right_hand_thumb_rota_tip" />
    <axis xyz="0 0 0" />
  </joint>
  <link name="right_hand_index_bend_link">
    <inertial>
      <origin xyz="1.36538073637754E-05 0.000296873462792606 0.00896968935652223" rpy="0 0 0" />
      <mass value="0.0678358392130179" />
      <inertia ixx="1.24579812319209E-05" ixy="-4.99427571319824E-10" ixz="1.65009806493775E-08" iyy="1.16208585294442E-05" iyz="-1.16944382314649E-06" izz="4.10931551097277E-06" />
    </inertial>
    <visual>
      <origin xyz="0 0 0" rpy="0 0 0" />
      <geometry>
        <mesh filename="./meshes/right_hand_index_bend_link.STL" />
      </geometry>
      <material name="">
        <color rgba="1 1 1 1" />
      </material>
    </visual>
    <!-- <collision>
      <origin xyz="0 0 0" rpy="0 0 0" />
      <geometry>
        <mesh filename="./meshes/right_hand_index_bend_link.STL" />
      </geometry>
    </collision> -->
  </link>
  <joint name="right_hand_index_bend_joint" type="revolute">
    <origin xyz="0.0265 0.0065 -0.0899" rpy="0 0 0" />
    <parent link="right_hand_link" />
    <child link="right_hand_index_bend_link" />
    <axis xyz="0 -1 0" />
    <limit lower="-0.175" upper="0.175" effort="0.4" velocity="14.38" />
    <dynamics damping="1" friction="1" />
  </joint>
  <link name="right_hand_index_rota_link1">
    <inertial>
      <origin xyz="1.33096190413698E-05 -0.00117935414486181 -0.0314667599966276" rpy="0 0 0" />
      <mass value="0.0630022977710548" />
      <inertia ixx="1.27456069380942E-05" ixy="1.11699686434991E-08" ixz="6.33463870143636E-08" iyy="1.13159521343031E-05" iyz="7.4065245190496E-08" izz="3.96846198628846E-06" />
    </inertial>
    <visual>
      <origin xyz="0 0 0" rpy="0 0 0" />
      <geometry>
        <mesh filename="./meshes/right_hand_index_rota_link1.STL" />
      </geometry>
      <material name="">
        <color rgba="1 1 1 1" />
      </material>
    </visual>
    <collision>
      <origin xyz="0 0 0" rpy="0 0 0" />
      <geometry>
        <mesh filename="./meshes/right_hand_index_rota_link1.STL" />
      </geometry>
    </collision>
  </link>
  <joint name="right_hand_index_joint1" type="revolute">
    <origin xyz="0 0 -0.0178" rpy="0 0 0" />
    <parent link="right_hand_index_bend_link" />
    <child link="right_hand_index_rota_link1" />
    <axis xyz="1 0 0" />
    <limit lower="0" upper="1.92" effort="1.1" velocity="8.63" />
    <dynamics damping="1" friction="1" />
  </joint>
  <link name="right_hand_index_rota_link2">
    <inertial>
      <origin xyz="-0.000105984925346917 -0.000552347223434896 -0.0269533774745725" rpy="0 0 0" />
      <mass value="0.0179783067962212" />
      <inertia ixx="1.57447652121885E-06" ixy="2.76146302574291E-09" ixz="2.28756514040053E-08" iyy="1.41206918406645E-06" iyz="7.17000488972861E-09" izz="9.25906469039188E-07" />
    </inertial>
    <visual>
      <origin xyz="0 0 0" rpy="0 0 0" />
      <geometry>
        <mesh filename="./meshes/right_hand_index_rota_link2.STL" />
      </geometry>
      <material name="">
        <color rgba="0.866666666666667 0.866666666666667 0.890196078431372 1" />
      </material>
    </visual>
    <collision>
      <origin xyz="0 0 0" rpy="0 0 0" />
      <geometry>
        <mesh filename="./meshes/right_hand_index_rota_link2.STL" />
      </geometry>
    </collision>
  </link>
  <joint name="right_hand_index_joint2" type="revolute">
    <origin xyz="0 0 -0.0558" rpy="0 0 0" />
    <parent link="right_hand_index_rota_link1" />
    <child link="right_hand_index_rota_link2" />
    <axis xyz="1 0 0" />
    <limit lower="0" upper="1.92" effort="0.4" velocity="14.38" />
    <dynamics damping="1" friction="1" />
  </joint>
  <link name="right_hand_index_rota_tip">
    <inertial>
      <origin xyz="-5.05845365594837E-15 4.55364912443912E-16 0" rpy="0 0 0" />
      <mass value="3.53429173528852E-08" />
      <inertia ixx="3.97607820219958E-14" ixy="7.48111122560063E-29" ixz="-4.64935595683389E-31" iyy="9.35114688295087E-14" iyz="1.95060746234015E-42" izz="9.35114688295087E-14" />
    </inertial>
    <visual>
      <origin xyz="0 0 0" rpy="0 0 0" />
      <geometry>
        <mesh filename="./meshes/right_hand_index_rota_tip.STL" />
      </geometry>
      <material name="">
        <color rgba="0.698039215686274 0.698039215686274 0.698039215686274 1" />
      </material>
    </visual>
    <collision>
      <origin xyz="0 0 0" rpy="0 0 0" />
      <geometry>
        <mesh filename="./meshes/right_hand_index_rota_tip.STL" />
      </geometry>
    </collision>
  </link>
  <joint name="right_hand_index_rota_joint3" type="fixed">
    <origin xyz="0 0 -0.0425000000000002" rpy="0 0 0" />
    <parent link="right_hand_index_rota_link2" />
    <child link="right_hand_index_rota_tip" />
    <axis xyz="0 0 0" />
  </joint>
  <link name="right_hand_mid_link1">
    <inertial>
      <origin xyz="1.33096499071285E-05 -0.00117935409999994 -0.0314667603905118" rpy="0 0 0" />
      <mass value="0.0630022982853768" />
      <inertia ixx="1.27456066969008E-05" ixy="1.11700232206898E-08" ixz="6.3346305251064E-08" iyy="1.13159520159902E-05" iyz="7.40649382191835E-08" izz="3.96846193278891E-06" />
    </inertial>
    <visual>
      <origin xyz="0 0 0" rpy="0 0 0" />
      <geometry>
        <mesh filename="./meshes/right_hand_mid_link1.STL" />
      </geometry>
      <material name="">
        <color rgba="1 1 1 1" />
      </material>
    </visual>
    <collision>
      <origin xyz="0 0 0" rpy="0 0 0" />
      <geometry>
        <mesh filename="./meshes/right_hand_mid_link1.STL" />
      </geometry>
    </collision>
  </link>
  <joint name="right_hand_mid_joint1" type="revolute">
    <origin xyz="0.004 0.0065 -0.1082" rpy="0 0 0" />
    <parent link="right_hand_link" />
    <child link="right_hand_mid_link1" />
    <axis xyz="1 0 0" />
    <limit lower="0" upper="1.92" effort="1.1" velocity="8.63" />
    <dynamics damping="1" friction="1" />
  </joint>
  <link name="right_hand_mid_link2">
    <inertial>
      <origin xyz="-0.000105984925042516 -0.000552347223516997 -0.0269533774743325" rpy="0 0 0" />
      <mass value="0.0179783067957322" />
      <inertia ixx="1.5744765211742E-06" ixy="2.76146300139653E-09" ixz="2.28756514545347E-08" iyy="1.41206918402052E-06" iyz="7.17000487544398E-09" izz="9.25906469030995E-07" />
    </inertial>
    <visual>
      <origin xyz="0 0 0" rpy="0 0 0" />
      <geometry>
        <mesh filename="./meshes/right_hand_mid_link2.STL" />
      </geometry>
      <material name="">
        <color rgba="0.866666666666667 0.866666666666667 0.890196078431372 1" />
      </material>
    </visual>
    <collision>
      <origin xyz="0 0 0" rpy="0 0 0" />
      <geometry>
        <mesh filename="./meshes/right_hand_mid_link2.STL" />
      </geometry>
    </collision>
  </link>
  <joint name="right_hand_mid_joint2" type="revolute">
    <origin xyz="0 0 -0.0558" rpy="0 0 0" />
    <parent link="right_hand_mid_link1" />
    <child link="right_hand_mid_link2" />
    <axis xyz="1 0 0" />
    <limit lower="0" upper="1.94" effort="0.4" velocity="14.38" />
    <dynamics damping="1" friction="1" />
  </joint>
  <link name="right_hand_mid_tip">
    <inertial>
      <origin xyz="-8.8037216405823E-16 -2.25002308451572E-14 -3.33066907387547E-16" rpy="0 0 0" />
      <mass value="3.53429173528852E-08" />
      <inertia ixx="3.97607820219958E-14" ixy="4.6998091400205E-29" ixz="1.72625026613961E-29" iyy="9.35114688295087E-14" iyz="-1.34632261157722E-30" izz="9.35114688295087E-14" />
    </inertial>
    <visual>
      <origin xyz="0 0 0" rpy="0 0 0" />
      <geometry>
        <mesh filename="./meshes/right_hand_mid_tip.STL" />
      </geometry>
      <material name="">
        <color rgba="0.698039215686274 0.698039215686274 0.698039215686274 1" />
      </material>
    </visual>
    <collision>
      <origin xyz="0 0 0" rpy="0 0 0" />
      <geometry>
        <mesh filename="./meshes/right_hand_mid_tip.STL" />
      </geometry>
    </collision>
  </link>
  <joint name="right_hand_mid_joint3" type="fixed">
    <origin xyz="0 0 -0.0424999999999994" rpy="0 0 0" />
    <parent link="right_hand_mid_link2" />
    <child link="right_hand_mid_tip" />
    <axis xyz="0 0 0" />
  </joint>
  <link name="right_hand_ring_link1">
    <inertial>
      <origin xyz="1.33094707849453E-05 -0.00117935508416771 -0.0314667595731168" rpy="0 0 0" />
      <mass value="0.0630023036931237" />
      <inertia ixx="1.27456080835049E-05" ixy="1.11699058261677E-08" ixz="6.33463652456311E-08" iyy="1.13159526955937E-05" iyz="7.4065582403629E-08" izz="3.96846269729939E-06" />
    </inertial>
    <visual>
      <origin xyz="0 0 0" rpy="0 0 0" />
      <geometry>
        <mesh filename="./meshes/right_hand_ring_link1.STL" />
      </geometry>
      <material name="">
        <color rgba="1 1 1 1" />
      </material>
    </visual>
    <collision>
      <origin xyz="0 0 0" rpy="0 0 0" />
      <geometry>
        <mesh filename="./meshes/right_hand_ring_link1.STL" />
      </geometry>
    </collision>
  </link>
  <joint name="right_hand_ring_joint1" type="revolute">
    <origin xyz="-0.016 0.0065 -0.1052" rpy="0 0 0" />
    <parent link="right_hand_link" />
    <child link="right_hand_ring_link1" />
    <axis xyz="1 0 0" />
    <limit lower="0" upper="1.92" effort="1.1" velocity="8.63" />
    <dynamics damping="1" friction="1" />
  </joint>
  <link name="right_hand_ring_link2">
    <inertial>
      <origin xyz="-0.000105983959785005 -0.000552346745385368 -0.0269533714070292" rpy="0 0 0" />
      <mass value="0.0179783089787658" />
      <inertia ixx="1.57447525401884E-06" ixy="2.76131932783415E-09" ixz="2.28751135554219E-08" iyy="1.41206796765122E-06" iyz="7.16912906776482E-09" izz="9.2590665289646E-07" />
    </inertial>
    <visual>
      <origin xyz="0 0 0" rpy="0 0 0" />
      <geometry>
        <mesh filename="./meshes/right_hand_ring_link2.STL" />
      </geometry>
      <material name="">
        <color rgba="0.866666666666667 0.866666666666667 0.890196078431372 1" />
      </material>
    </visual>
    <collision>
      <origin xyz="0 0 0" rpy="0 0 0" />
      <geometry>
        <mesh filename="./meshes/right_hand_ring_link2.STL" />
      </geometry>
    </collision>
  </link>
  <joint name="right_hand_ring_joint2" type="revolute">
    <origin xyz="0 0 -0.0558" rpy="0 0 0" />
    <parent link="right_hand_ring_link1" />
    <child link="right_hand_ring_link2" />
    <axis xyz="1 0 0" />
    <limit lower="0" upper="1.92" effort="0.4" velocity="14.38" />
    <dynamics damping="1" friction="1" />
  </joint>
  <link name="right_hand_ring_tip">
    <inertial>
      <origin xyz="-9.92261828258734E-16 -2.21350715534641E-15 -3.05311331771918E-16" rpy="0 0 0" />
      <mass value="3.53429173528852E-08" />
      <inertia ixx="3.97607820219958E-14" ixy="-3.04227363665443E-29" ixz="1.66902038668838E-29" iyy="9.35114688295086E-14" iyz="1.38336184398146E-41" izz="9.35114688295086E-14" />
    </inertial>
    <visual>
      <origin xyz="0 0 0" rpy="0 0 0" />
      <geometry>
        <mesh filename="./meshes/right_hand_ring_tip.STL" />
      </geometry>
      <material name="">
        <color rgba="0.698039215686274 0.698039215686274 0.698039215686274 1" />
      </material>
    </visual>
    <collision>
      <origin xyz="0 0 0" rpy="0 0 0" />
      <geometry>
        <mesh filename="./meshes/right_hand_ring_tip.STL" />
      </geometry>
    </collision>
  </link>
  <joint name="right_hand_ring_joint3" type="fixed">
    <origin xyz="0 0 -0.0424999999999994" rpy="0 0 0" />
    <parent link="right_hand_ring_link2" />
    <child link="right_hand_ring_tip" />
    <axis xyz="0 0 0" />
  </joint>
  <link name="right_hand_pinky_link1">
    <inertial>
      <origin xyz="1.33096583489756E-05 -0.0011793548140165 -0.0314667599567012" rpy="0 0 0" />
      <mass value="0.0630023023053313" />
      <inertia ixx="1.27456074891274E-05" ixy="1.11700339861832E-08" ixz="6.33462884921005E-08" iyy="1.13159522774957E-05" iyz="7.40652867581976E-08" izz="3.9684624682918E-06" />
    </inertial>
    <visual>
      <origin xyz="0 0 0" rpy="0 0 0" />
      <geometry>
        <mesh filename="./meshes/right_hand_pinky_link1.STL" />
      </geometry>
      <material name="">
        <color rgba="1 1 1 1" />
      </material>
    </visual>
    <collision>
      <origin xyz="0 0 0" rpy="0 0 0" />
      <geometry>
        <mesh filename="./meshes/right_hand_pinky_link1.STL" />
      </geometry>
    </collision>
  </link>
  <joint name="right_hand_pinky_joint1" type="revolute">
    <origin xyz="-0.036 0.0065 -0.1022" rpy="0 0 0" />
    <parent link="right_hand_link" />
    <child link="right_hand_pinky_link1" />
    <axis xyz="1 0 0" />
    <limit lower="0" upper="1.92" effort="1.1" velocity="8.63" />
    <dynamics damping="1" friction="1" />
  </joint>
  <link name="right_hand_pinky_link2">
    <inertial>
      <origin xyz="-0.000105984888530107 -0.000552347260036744 -0.0269533774032427" rpy="0 0 0" />
      <mass value="0.017978306641324" />
      <inertia ixx="1.57447650660388E-06" ixy="2.76145985777475E-09" ixz="2.28756571611184E-08" iyy="1.41206916992156E-06" iyz="7.16999887456573E-09" izz="9.25906462770731E-07" />
    </inertial>
    <visual>
      <origin xyz="0 0 0" rpy="0 0 0" />
      <geometry>
        <mesh filename="./meshes/right_hand_pinky_link2.STL" />
      </geometry>
      <material name="">
        <color rgba="0.866666666666667 0.866666666666667 0.890196078431372 1" />
      </material>
    </visual>
    <collision>
      <origin xyz="0 0 0" rpy="0 0 0" />
      <geometry>
        <mesh filename="./meshes/right_hand_pinky_link2.STL" />
      </geometry>
    </collision>
  </link>
  <joint name="right_hand_pinky_joint2" type="revolute">
    <origin xyz="0 0 -0.0558" rpy="0 0 0" />
    <parent link="right_hand_pinky_link1" />
    <child link="right_hand_pinky_link2" />
    <axis xyz="1 0 0" />
    <limit lower="0" upper="1.92" effort="0.4" velocity="14.38" />
    <dynamics damping="1" friction="1" />
  </joint>
  <link name="right_hand_pinky_tip">
    <inertial>
      <origin xyz="-1.00613961606655E-15 3.60822483003176E-16 -3.05311331771918E-16" rpy="0 0 0" />
      <mass value="3.53429173528851E-08" />
      <inertia ixx="3.97607820219958E-14" ixy="-2.67491914041387E-29" ixz="2.03175360376622E-28" iyy="9.35114688295085E-14" iyz="1.39008807661022E-41" izz="9.35114688295085E-14" />
    </inertial>
    <visual>
      <origin xyz="0 0 0" rpy="0 0 0" />
      <geometry>
        <mesh filename="./meshes/right_hand_pinky_tip.STL" />
      </geometry>
      <material name="">
        <color rgba="0.698039215686274 0.698039215686274 0.698039215686274 1" />
      </material>
    </visual>
    <collision>
      <origin xyz="0 0 0" rpy="0 0 0" />
      <geometry>
        <mesh filename="./meshes/right_hand_pinky_tip.STL" />
      </geometry>
    </collision>
  </link>
  <joint name="right_hand_pinky_joint3" type="fixed">
    <origin xyz="0 0 -0.0424999999999994" rpy="0 0 0" />
    <parent link="right_hand_pinky_link2" />
    <child link="right_hand_pinky_tip" />
    <axis xyz="0 0 0" />
  </joint>
  <link name="right_hand_ee_link">
    <inertial>
      <origin xyz="2.53177486972285E-18 3.50815468491248E-16 0" rpy="0 0 0" />
      <mass value="3.53429173528852E-08" />
      <inertia ixx="3.97607820219958E-14" ixy="4.74909746440606E-29" ixz="1.39310580749999E-28" iyy="9.35114688295087E-14" iyz="1.37198229082169E-41" izz="9.35114688295087E-14" />
    </inertial>
    <visual>
      <origin xyz="0 0 0" rpy="0 0 0" />
      <geometry>
        <mesh filename="./meshes/right_hand_ee_link.STL" />
      </geometry>
      <material name="">
        <color rgba="0.698039215686274 0.698039215686274 0.698039215686274 1" />
      </material>
    </visual>
    <collision>
      <origin xyz="0 0 0" rpy="0 0 0" />
      <geometry>
        <mesh filename="./meshes/right_hand_ee_link.STL" />
      </geometry>
    </collision>
  </link>
  <joint name="right_hand_ee_joint" type="fixed">
    <origin xyz="0 0 -0.065" rpy="0 0 0" />
    <parent link="right_hand_link" />
    <child link="right_hand_ee_link" />
    <axis xyz="0 0 0" />
  </joint>
</robot>