<?xml version="1.0" encoding="UTF-8"?>
<robot name="realman_xhand_left">
  <joint name="FixedJoint" type="fixed">
    <origin xyz="0.0020915 0. 0. " rpy="0. 1.5707963 0. "/>
    <parent link="Link7"/>
    <child link="Cylinder_link"/>
  </joint>
  <joint name="FixedJoint0" type="fixed">
    <origin xyz="0. 0. 0." rpy="3.1415927. 0. -1.5707928"/>
    <parent link="Cylinder_link"/>
    <child link="xhand_left_base_link"/>
  </joint>
  <joint name="joint1" type="revolute">
    <origin xyz="0. 0. 0.2405" rpy="3.1415927 -1.5707928 1.5707964"/>
    <parent link="realman_xhand_left_rm_75_6f_description_rm_75_6f_description_base_link"/>
    <child link="Link1"/>
    <axis xyz="1. 0. 0."/>
    <limit lower="-3.1070001" upper="3.1070001" effort="100." velocity="1."/>
  </joint>
  <joint name="joint2" type="revolute">
    <origin xyz="0. 0. 0." rpy="3.1415927 -1.5707928 0. "/>
    <parent link="Link1"/>
    <child link="Link2"/>
    <axis xyz="1. 0. 0."/>
    <limit lower="-2.2689999" upper="2.2689999" effort="100." velocity="1."/>
  </joint>
  <joint name="joint3" type="revolute">
    <origin xyz="0. 0. 0.256" rpy="3.1415927 -1.5707928 0. "/>
    <parent link="Link2"/>
    <child link="Link3"/>
    <axis xyz="1. 0. 0."/>
    <limit lower="-3.1070001" upper="3.1070001" effort="100." velocity="1."/>
  </joint>
  <joint name="joint4" type="revolute">
    <origin xyz="0. 0. 0." rpy="3.1415927 -1.5707928 0. "/>
    <parent link="Link3"/>
    <child link="Link4"/>
    <axis xyz="1. 0. 0."/>
    <limit lower="-2.3559998" upper="2.3559998" effort="100." velocity="1."/>
  </joint>
  <joint name="joint5" type="revolute">
    <origin xyz="0. 0. 0.21" rpy="3.1415927 -1.5707928 0. "/>
    <parent link="Link4"/>
    <child link="Link5"/>
    <axis xyz="1. 0. 0."/>
    <limit lower="-3.1070001" upper="3.1070001" effort="100." velocity="1."/>
  </joint>
  <joint name="joint6" type="revolute">
    <origin xyz="0. 0. 0." rpy="3.1415927 -1.5707928 0. "/>
    <parent link="Link5"/>
    <child link="Link6"/>
    <axis xyz="1. 0. 0."/>
    <limit lower="-2.2339999" upper="2.2339999" effort="100." velocity="1."/>
  </joint>
  <joint name="joint7" type="revolute">
    <origin xyz="0. 0. 0.1725" rpy="-1.5707964 -1.5707964 0. "/>
    <parent link="Link6"/>
    <child link="Link7"/>
    <axis xyz="1. 0. 0."/>
    <limit lower="-6.2829994" upper="6.2829994" effort="100." velocity="1."/>
  </joint>
  <joint name="left_hand_index_bend_joint" type="revolute">
    <origin xyz="0.0265 -0.0065 -0.0899" rpy="3.1415927 0. 0. "/>
    <parent link="xhand_left_base_link"/>
    <child link="left_hand_index_bend_link"/>
    <axis xyz="0. 1. 0."/>
    <limit lower="-0.175" upper="0.175" effort="0.4" velocity="14.3800004"/>
  </joint>
  <joint name="left_hand_index_joint1" type="revolute">
    <origin xyz="0. 0. 0.0178" rpy="3.1415927 0. 3.1415927"/>
    <parent link="left_hand_index_bend_link"/>
    <child link="left_hand_index_rota_link1"/>
    <axis xyz="1. 0. 0."/>
    <limit lower="0." upper="1.9199999" effort="1.1" velocity="8.6300001"/>
  </joint>
  <joint name="left_hand_index_joint2" type="revolute">
    <origin xyz="0. 0. -0.0558" rpy="0. 0. 0."/>
    <parent link="left_hand_index_rota_link1"/>
    <child link="left_hand_index_rota_link2"/>
    <axis xyz="1. 0. 0."/>
    <limit lower="0." upper="1.9199999" effort="0.4" velocity="14.3800004"/>
  </joint>
  <joint name="left_hand_mid_joint1" type="revolute">
    <origin xyz="0.004 -0.0065 -0.1082" rpy="0. 0. 3.1415927"/>
    <parent link="xhand_left_base_link"/>
    <child link="left_hand_mid_link1"/>
    <axis xyz="1. 0. 0."/>
    <limit lower="0." upper="1.9199999" effort="1.1" velocity="8.6300001"/>
  </joint>
  <joint name="left_hand_mid_joint2" type="revolute">
    <origin xyz="0. 0. -0.0558" rpy="0. 0. 0."/>
    <parent link="left_hand_mid_link1"/>
    <child link="left_hand_mid_link2"/>
    <axis xyz="1. 0. 0."/>
    <limit lower="0." upper="1.9199999" effort="0.4" velocity="14.3800004"/>
  </joint>
  <joint name="left_hand_pinky_joint1" type="revolute">
    <origin xyz="-0.036 -0.0065 -0.1022" rpy="0. 0. 3.1415927"/>
    <parent link="xhand_left_base_link"/>
    <child link="left_hand_pinky_link1"/>
    <axis xyz="1. 0. 0."/>
    <limit lower="0." upper="1.9199999" effort="1.1" velocity="8.6300001"/>
  </joint>
  <joint name="left_hand_pinky_joint2" type="revolute">
    <origin xyz="0. 0. -0.0558" rpy="0. 0. 0."/>
    <parent link="left_hand_pinky_link1"/>
    <child link="left_hand_pinky_link2"/>
    <axis xyz="1. 0. 0."/>
    <limit lower="0." upper="1.9199999" effort="0.4" velocity="14.3800004"/>
  </joint>
  <joint name="left_hand_ring_joint1" type="revolute">
    <origin xyz="-0.016 -0.0065 -0.1052" rpy="0. 0. 3.1415927"/>
    <parent link="xhand_left_base_link"/>
    <child link="left_hand_ring_link1"/>
    <axis xyz="1. 0. 0."/>
    <limit lower="0." upper="1.9199999" effort="1.1" velocity="8.6300001"/>
  </joint>
  <joint name="left_hand_ring_joint2" type="revolute">
    <origin xyz="0. 0. -0.0558" rpy="0. 0. 0."/>
    <parent link="left_hand_ring_link1"/>
    <child link="left_hand_ring_link2"/>
    <axis xyz="1. 0. 0."/>
    <limit lower="0." upper="1.9199999" effort="0.4" velocity="14.3800004"/>
  </joint>
  <joint name="left_hand_thumb_bend_joint" type="revolute">
    <origin xyz="0.0228 -0.0095 -0.0305" rpy="3.1415927 0. 3.1415927"/>
    <parent link="xhand_left_base_link"/>
    <child link="left_hand_thumb_bend_link"/>
    <axis xyz="0. 0. 1."/>
    <limit lower="0." upper="1.8299999" effort="1.1" velocity="8.6300001"/>
  </joint>
  <joint name="left_hand_thumb_rota_joint1" type="revolute">
    <origin xyz="-0.0285986 -0.0083177 -0.00178 " rpy="2.8797932 -0. -3.1008923"/>
    <parent link="left_hand_thumb_bend_link"/>
    <child link="left_hand_thumb_rota_link1"/>
    <axis xyz="0. 1. 0."/>
    <limit lower="-1.0499999" upper="1.5699999" effort="1.1" velocity="8.6300001"/>
  </joint>
  <joint name="left_hand_thumb_rota_joint2" type="revolute">
    <origin xyz="0.0553 0. 0. " rpy="0. 0. 0."/>
    <parent link="left_hand_thumb_rota_link1"/>
    <child link="left_hand_thumb_rota_link2"/>
    <axis xyz="0. 1. 0."/>
    <limit lower="-0.17" upper="1.8299999" effort="0.4" velocity="14.3800004"/>
  </joint>
  <joint name="root_joint" type="fixed">
    <origin xyz="0. 0. 0." rpy="0. 0. 0."/>
    <parent link="Root"/>
    <child link="realman_xhand_left_rm_75_6f_description_rm_75_6f_description_base_link"/>
  </joint>
  <link name="Cylinder_link">
    <visual>
      <origin xyz="0. 0. 0.001843" rpy="3.1415927 0. 1.5707964"/>
      <geometry>
        <cylinder radius="0.02845" length="0.0038"/>
      </geometry>
    </visual>
    <collision>
      <origin xyz="0. 0. 0.001843" rpy="3.1415927 0. 1.5707964"/>
      <geometry>
        <cylinder radius="0.02845" length="0.0038"/>
      </geometry>
    </collision>
  </link>
  <link name="Link1">
    <inertial>
      <origin xyz="0. 0. 0." rpy="0. 0. 0."/>
      <mass value="0.59356"/>
      <inertia ixx="0." ixy="0." ixz="0." iyy="0." iyz="0." izz="0."/>
    </inertial>
    <visual>
      <origin xyz="0. 0. 0." rpy="0. 0. 1.5707964"/>
      <geometry>
        <mesh filename="meshes/Link1_visuals.obj" scale="1. 1. 1."/>
      </geometry>
    </visual>
    <visual>
      <origin xyz="0. 0. 0." rpy="0. 0. 1.5707964"/>
      <geometry>
        <mesh filename="meshes/Link1_collisions.obj" scale="1. 1. 1."/>
      </geometry>
    </visual>
    <collision>
      <origin xyz="0. 0. 0." rpy="0. 0. 1.5707964"/>
      <geometry>
        <mesh filename="meshes/Link1_collisions.obj" scale="1. 1. 1."/>
      </geometry>
    </collision>
  </link>
  <link name="Link2">
    <inertial>
      <origin xyz="0. 0. 0." rpy="0. 0. 0."/>
      <mass value="0.43285"/>
      <inertia ixx="0." ixy="0." ixz="0." iyy="0." iyz="0." izz="0."/>
    </inertial>
    <visual>
      <origin xyz="0. 0. 0." rpy="0. 0. -1.5707964"/>
      <geometry>
        <mesh filename="meshes/Link2_visuals.obj" scale="1. 1. 1."/>
      </geometry>
    </visual>
    <visual>
      <origin xyz="0. 0. 0." rpy="0. 0. -1.5707964"/>
      <geometry>
        <mesh filename="meshes/Link2_collisions.obj" scale="1. 1. 1."/>
      </geometry>
    </visual>
    <collision>
      <origin xyz="0. 0. 0." rpy="0. 0. -1.5707964"/>
      <geometry>
        <mesh filename="meshes/Link2_collisions.obj" scale="1. 1. 1."/>
      </geometry>
    </collision>
  </link>
  <link name="Link3">
    <inertial>
      <origin xyz="0. 0. 0." rpy="0. 0. 0."/>
      <mass value="0.43132"/>
      <inertia ixx="0." ixy="0." ixz="0." iyy="0." iyz="0." izz="0."/>
    </inertial>
    <visual>
      <origin xyz="0. 0. 0." rpy="0. 0. 1.5707964"/>
      <geometry>
        <mesh filename="meshes/Link3_visuals.obj" scale="1. 1. 1."/>
      </geometry>
    </visual>
    <visual>
      <origin xyz="0. 0. 0." rpy="0. 0. 1.5707964"/>
      <geometry>
        <mesh filename="meshes/Link3_collisions.obj" scale="1. 1. 1."/>
      </geometry>
    </visual>
    <collision>
      <origin xyz="0. 0. 0." rpy="0. 0. 1.5707964"/>
      <geometry>
        <mesh filename="meshes/Link3_collisions.obj" scale="1. 1. 1."/>
      </geometry>
    </collision>
  </link>
  <link name="Link4">
    <inertial>
      <origin xyz="0. 0. 0." rpy="0. 0. 0."/>
      <mass value="0.28963"/>
      <inertia ixx="0." ixy="0." ixz="0." iyy="0." iyz="0." izz="0."/>
    </inertial>
    <visual>
      <origin xyz="0. 0. 0." rpy="0. 0. -1.5707964"/>
      <geometry>
        <mesh filename="meshes/Link4_visuals.obj" scale="1. 1. 1."/>
      </geometry>
    </visual>
    <visual>
      <origin xyz="0. 0. 0." rpy="0. 0. -1.5707964"/>
      <geometry>
        <mesh filename="meshes/Link4_collisions.obj" scale="1. 1. 1."/>
      </geometry>
    </visual>
    <collision>
      <origin xyz="0. 0. 0." rpy="0. 0. -1.5707964"/>
      <geometry>
        <mesh filename="meshes/Link4_collisions.obj" scale="1. 1. 1."/>
      </geometry>
    </collision>
  </link>
  <link name="Link5">
    <inertial>
      <origin xyz="0. 0. 0." rpy="0. 0. 0."/>
      <mass value="0.23941"/>
      <inertia ixx="0." ixy="0." ixz="0." iyy="0." iyz="0." izz="0."/>
    </inertial>
    <visual>
      <origin xyz="0. 0. 0." rpy="0. 0. 1.5707964"/>
      <geometry>
        <mesh filename="meshes/Link5_visuals.obj" scale="1. 1. 1."/>
      </geometry>
    </visual>
    <visual>
      <origin xyz="0. 0. 0." rpy="0. 0. 1.5707964"/>
      <geometry>
        <mesh filename="meshes/Link5_collisions.obj" scale="1. 1. 1."/>
      </geometry>
    </visual>
    <collision>
      <origin xyz="0. 0. 0." rpy="0. 0. 1.5707964"/>
      <geometry>
        <mesh filename="meshes/Link5_collisions.obj" scale="1. 1. 1."/>
      </geometry>
    </collision>
  </link>
  <link name="Link6">
    <inertial>
      <origin xyz="0. 0. 0." rpy="0. 0. 0."/>
      <mass value="0.21879"/>
      <inertia ixx="0." ixy="0." ixz="0." iyy="0." iyz="0." izz="0."/>
    </inertial>
    <visual>
      <origin xyz="0. 0. 0." rpy="0. 0. -1.5707964"/>
      <geometry>
        <mesh filename="meshes/Link6_visuals.obj" scale="1. 1. 1."/>
      </geometry>
    </visual>
    <visual>
      <origin xyz="0. 0. 0." rpy="0. 0. -1.5707964"/>
      <geometry>
        <mesh filename="meshes/Link6_collisions.obj" scale="1. 1. 1."/>
      </geometry>
    </visual>
    <collision>
      <origin xyz="0. 0. 0." rpy="0. 0. -1.5707964"/>
      <geometry>
        <mesh filename="meshes/Link6_collisions.obj" scale="1. 1. 1."/>
      </geometry>
    </collision>
  </link>
  <link name="Link7">
    <inertial>
      <origin xyz="0. 0. 0." rpy="0. 0. 0."/>
      <mass value="0.14433"/>
      <inertia ixx="0." ixy="0." ixz="0." iyy="0." iyz="0." izz="0."/>
    </inertial>
    <visual>
      <origin xyz="0. 0. 0." rpy="0. 1.5707963 0. "/>
      <geometry>
        <mesh filename="meshes/Link7_visuals.obj" scale="1. 1. 1."/>
      </geometry>
    </visual>
    <visual>
      <origin xyz="0. 0. 0." rpy="0. 1.5707963 0. "/>
      <geometry>
        <mesh filename="meshes/Link7_collisions.obj" scale="1. 1. 1."/>
      </geometry>
    </visual>
    <collision>
      <origin xyz="0. 0. 0." rpy="0. 1.5707963 0. "/>
      <geometry>
        <mesh filename="meshes/Link7_collisions.obj" scale="1. 1. 1."/>
      </geometry>
    </collision>
  </link>
  <link name="Root"/>
  <link name="left_hand_index_bend_link">
    <inertial>
      <origin xyz="0. 0. 0." rpy="0. 0. 0."/>
      <mass value="0.0678358"/>
      <inertia ixx="0." ixy="0." ixz="0." iyy="0." iyz="0." izz="0."/>
    </inertial>
    <visual>
      <origin xyz="0. 0. 0." rpy="3.1415927 0. 0. "/>
      <geometry>
        <mesh filename="meshes/left_hand_index_bend_link_visuals_mesh_0.obj" scale="1. 1. 1."/>
      </geometry>
    </visual>
  </link>
  <link name="left_hand_index_rota_link1">
    <inertial>
      <origin xyz="0. 0. 0." rpy="0. 0. 0."/>
      <mass value="0.0630023"/>
      <inertia ixx="0." ixy="0." ixz="0." iyy="0." iyz="0." izz="0."/>
    </inertial>
    <visual>
      <origin xyz="0. 0. 0." rpy="0. 0. 3.1415927"/>
      <geometry>
        <mesh filename="meshes/left_hand_index_rota_link1_visuals_mesh_0.obj" scale="1. 1. 1."/>
      </geometry>
    </visual>
    <visual>
      <origin xyz="0. 0. 0." rpy="0. 0. 3.1415927"/>
      <geometry>
        <mesh filename="meshes/left_hand_index_rota_link1_collisions_mesh_0.obj" scale="1. 1. 1."/>
      </geometry>
    </visual>
    <collision>
      <origin xyz="0. 0. 0." rpy="0. 0. 3.1415927"/>
      <geometry>
        <mesh filename="meshes/left_hand_index_rota_link1_collisions_mesh_0.obj" scale="1. 1. 1."/>
      </geometry>
    </collision>
  </link>
  <link name="left_hand_index_rota_link2">
    <inertial>
      <origin xyz="0. 0. 0." rpy="0. 0. 0."/>
      <mass value="0.0179783"/>
      <inertia ixx="0." ixy="0." ixz="0." iyy="0." iyz="0." izz="0."/>
    </inertial>
    <visual>
      <origin xyz="0. 0. 0." rpy="0. 0. 3.1415927"/>
      <geometry>
        <mesh filename="meshes/left_hand_index_rota_link2_visuals_mesh_0.obj" scale="1. 1. 1."/>
      </geometry>
    </visual>
    <visual>
      <origin xyz="0. 0. -0.0425" rpy="0. 0. 3.1415927"/>
      <geometry>
        <mesh filename="meshes/left_hand_index_rota_link2_visuals_mesh_1.obj" scale="1. 1. 1."/>
      </geometry>
    </visual>
    <visual>
      <origin xyz="0. 0. 0." rpy="0. 0. 3.1415927"/>
      <geometry>
        <mesh filename="meshes/left_hand_index_rota_link2_collisions_mesh_0.obj" scale="1. 1. 1."/>
      </geometry>
    </visual>
    <visual>
      <origin xyz="0. 0. -0.0425" rpy="0. 0. 3.1415927"/>
      <geometry>
        <mesh filename="meshes/left_hand_index_rota_link2_collisions_mesh_1.obj" scale="1. 1. 1."/>
      </geometry>
    </visual>
    <collision>
      <origin xyz="0. 0. 0." rpy="0. 0. 3.1415927"/>
      <geometry>
        <mesh filename="meshes/left_hand_index_rota_link2_collisions_mesh_0.obj" scale="1. 1. 1."/>
      </geometry>
    </collision>
    <collision>
      <origin xyz="0. 0. -0.0425" rpy="0. 0. 3.1415927"/>
      <geometry>
        <mesh filename="meshes/left_hand_index_rota_link2_collisions_mesh_1.obj" scale="1. 1. 1."/>
      </geometry>
    </collision>
  </link>
  <link name="left_hand_mid_link1">
    <inertial>
      <origin xyz="0. 0. 0." rpy="0. 0. 0."/>
      <mass value="0.0630023"/>
      <inertia ixx="0." ixy="0." ixz="0." iyy="0." iyz="0." izz="0."/>
    </inertial>
    <visual>
      <origin xyz="0. 0. 0." rpy="0. 0. 3.1415927"/>
      <geometry>
        <mesh filename="meshes/left_hand_mid_link1_visuals_mesh_0.obj" scale="1. 1. 1."/>
      </geometry>
    </visual>
    <visual>
      <origin xyz="0. 0. 0." rpy="0. 0. 3.1415927"/>
      <geometry>
        <mesh filename="meshes/left_hand_mid_link1_collisions_mesh_0.obj" scale="1. 1. 1."/>
      </geometry>
    </visual>
    <collision>
      <origin xyz="0. 0. 0." rpy="0. 0. 3.1415927"/>
      <geometry>
        <mesh filename="meshes/left_hand_mid_link1_collisions_mesh_0.obj" scale="1. 1. 1."/>
      </geometry>
    </collision>
  </link>
  <link name="left_hand_mid_link2">
    <inertial>
      <origin xyz="0. 0. 0." rpy="0. 0. 0."/>
      <mass value="0.0179783"/>
      <inertia ixx="0." ixy="0." ixz="0." iyy="0." iyz="0." izz="0."/>
    </inertial>
    <visual>
      <origin xyz="0. 0. 0." rpy="0. 0. 3.1415927"/>
      <geometry>
        <mesh filename="meshes/left_hand_mid_link2_visuals_mesh_0.obj" scale="1. 1. 1."/>
      </geometry>
    </visual>
    <visual>
      <origin xyz="0. 0. -0.0425" rpy="0. 0. 3.1415927"/>
      <geometry>
        <mesh filename="meshes/left_hand_mid_link2_visuals_mesh_1.obj" scale="1. 1. 1."/>
      </geometry>
    </visual>
    <visual>
      <origin xyz="0. 0. 0." rpy="0. 0. 3.1415927"/>
      <geometry>
        <mesh filename="meshes/left_hand_mid_link2_collisions_mesh_0.obj" scale="1. 1. 1."/>
      </geometry>
    </visual>
    <visual>
      <origin xyz="0. 0. -0.0425" rpy="0. 0. 3.1415927"/>
      <geometry>
        <mesh filename="meshes/left_hand_mid_link2_collisions_mesh_1.obj" scale="1. 1. 1."/>
      </geometry>
    </visual>
    <collision>
      <origin xyz="0. 0. 0." rpy="0. 0. 3.1415927"/>
      <geometry>
        <mesh filename="meshes/left_hand_mid_link2_collisions_mesh_0.obj" scale="1. 1. 1."/>
      </geometry>
    </collision>
    <collision>
      <origin xyz="0. 0. -0.0425" rpy="0. 0. 3.1415927"/>
      <geometry>
        <mesh filename="meshes/left_hand_mid_link2_collisions_mesh_1.obj" scale="1. 1. 1."/>
      </geometry>
    </collision>
  </link>
  <link name="left_hand_pinky_link1">
    <inertial>
      <origin xyz="0. 0. 0." rpy="0. 0. 0."/>
      <mass value="0.0630023"/>
      <inertia ixx="0." ixy="0." ixz="0." iyy="0." iyz="0." izz="0."/>
    </inertial>
    <visual>
      <origin xyz="0. 0. 0." rpy="0. 0. 3.1415927"/>
      <geometry>
        <mesh filename="meshes/left_hand_pinky_link1_visuals_mesh_0.obj" scale="1. 1. 1."/>
      </geometry>
    </visual>
    <visual>
      <origin xyz="0. 0. 0." rpy="0. 0. 3.1415927"/>
      <geometry>
        <mesh filename="meshes/left_hand_pinky_link1_collisions_mesh_0.obj" scale="1. 1. 1."/>
      </geometry>
    </visual>
    <collision>
      <origin xyz="0. 0. 0." rpy="0. 0. 3.1415927"/>
      <geometry>
        <mesh filename="meshes/left_hand_pinky_link1_collisions_mesh_0.obj" scale="1. 1. 1."/>
      </geometry>
    </collision>
  </link>
  <link name="left_hand_pinky_link2">
    <inertial>
      <origin xyz="0. 0. 0." rpy="0. 0. 0."/>
      <mass value="0.0179783"/>
      <inertia ixx="0." ixy="0." ixz="0." iyy="0." iyz="0." izz="0."/>
    </inertial>
    <visual>
      <origin xyz="0. 0. 0." rpy="0. 0. 3.1415927"/>
      <geometry>
        <mesh filename="meshes/left_hand_pinky_link2_visuals_mesh_0.obj" scale="1. 1. 1."/>
      </geometry>
    </visual>
    <visual>
      <origin xyz="0. 0. -0.0425" rpy="0. 0. 3.1415927"/>
      <geometry>
        <mesh filename="meshes/left_hand_pinky_link2_visuals_mesh_1.obj" scale="1. 1. 1."/>
      </geometry>
    </visual>
    <visual>
      <origin xyz="0. 0. 0." rpy="0. 0. 3.1415927"/>
      <geometry>
        <mesh filename="meshes/left_hand_pinky_link2_collisions_mesh_0.obj" scale="1. 1. 1."/>
      </geometry>
    </visual>
    <visual>
      <origin xyz="0. 0. -0.0425" rpy="0. 0. 3.1415927"/>
      <geometry>
        <mesh filename="meshes/left_hand_pinky_link2_collisions_mesh_1.obj" scale="1. 1. 1."/>
      </geometry>
    </visual>
    <collision>
      <origin xyz="0. 0. 0." rpy="0. 0. 3.1415927"/>
      <geometry>
        <mesh filename="meshes/left_hand_pinky_link2_collisions_mesh_0.obj" scale="1. 1. 1."/>
      </geometry>
    </collision>
    <collision>
      <origin xyz="0. 0. -0.0425" rpy="0. 0. 3.1415927"/>
      <geometry>
        <mesh filename="meshes/left_hand_pinky_link2_collisions_mesh_1.obj" scale="1. 1. 1."/>
      </geometry>
    </collision>
  </link>
  <link name="left_hand_ring_link1">
    <inertial>
      <origin xyz="0. 0. 0." rpy="0. 0. 0."/>
      <mass value="0.0630023"/>
      <inertia ixx="0." ixy="0." ixz="0." iyy="0." iyz="0." izz="0."/>
    </inertial>
    <visual>
      <origin xyz="0. 0. 0." rpy="0. 0. 3.1415927"/>
      <geometry>
        <mesh filename="meshes/left_hand_ring_link1_visuals_mesh_0.obj" scale="1. 1. 1."/>
      </geometry>
    </visual>
    <visual>
      <origin xyz="0. 0. 0." rpy="0. 0. 3.1415927"/>
      <geometry>
        <mesh filename="meshes/left_hand_ring_link1_collisions_mesh_0.obj" scale="1. 1. 1."/>
      </geometry>
    </visual>
    <collision>
      <origin xyz="0. 0. 0." rpy="0. 0. 3.1415927"/>
      <geometry>
        <mesh filename="meshes/left_hand_ring_link1_collisions_mesh_0.obj" scale="1. 1. 1."/>
      </geometry>
    </collision>
  </link>
  <link name="left_hand_ring_link2">
    <inertial>
      <origin xyz="0. 0. 0." rpy="0. 0. 0."/>
      <mass value="0.0179783"/>
      <inertia ixx="0." ixy="0." ixz="0." iyy="0." iyz="0." izz="0."/>
    </inertial>
    <visual>
      <origin xyz="0. 0. 0." rpy="0. 0. 3.1415927"/>
      <geometry>
        <mesh filename="meshes/left_hand_ring_link2_visuals_mesh_0.obj" scale="1. 1. 1."/>
      </geometry>
    </visual>
    <visual>
      <origin xyz="0. 0. -0.0425" rpy="0. 0. 3.1415927"/>
      <geometry>
        <mesh filename="meshes/left_hand_ring_link2_visuals_mesh_1.obj" scale="1. 1. 1."/>
      </geometry>
    </visual>
    <visual>
      <origin xyz="0. 0. 0." rpy="0. 0. 3.1415927"/>
      <geometry>
        <mesh filename="meshes/left_hand_ring_link2_collisions_mesh_0.obj" scale="1. 1. 1."/>
      </geometry>
    </visual>
    <visual>
      <origin xyz="0. 0. -0.0425" rpy="0. 0. 3.1415927"/>
      <geometry>
        <mesh filename="meshes/left_hand_ring_link2_collisions_mesh_1.obj" scale="1. 1. 1."/>
      </geometry>
    </visual>
    <collision>
      <origin xyz="0. 0. 0." rpy="0. 0. 3.1415927"/>
      <geometry>
        <mesh filename="meshes/left_hand_ring_link2_collisions_mesh_0.obj" scale="1. 1. 1."/>
      </geometry>
    </collision>
    <collision>
      <origin xyz="0. 0. -0.0425" rpy="0. 0. 3.1415927"/>
      <geometry>
        <mesh filename="meshes/left_hand_ring_link2_collisions_mesh_1.obj" scale="1. 1. 1."/>
      </geometry>
    </collision>
  </link>
  <link name="left_hand_thumb_bend_link">
    <inertial>
      <origin xyz="0. 0. 0." rpy="0. 0. 0."/>
      <mass value="0.0098879"/>
      <inertia ixx="0." ixy="0." ixz="0." iyy="0." iyz="0." izz="0."/>
    </inertial>
    <visual>
      <origin xyz="0. 0. 0." rpy="3.1415927 0. 3.1415927"/>
      <geometry>
        <mesh filename="meshes/left_hand_thumb_bend_link_visuals_mesh_0.obj" scale="1. 1. 1."/>
      </geometry>
    </visual>
  </link>
  <link name="left_hand_thumb_rota_link1">
    <inertial>
      <origin xyz="0. 0. 0." rpy="0. 0. 0."/>
      <mass value="0.153155"/>
      <inertia ixx="0." ixy="0." ixz="0." iyy="0." iyz="0." izz="0."/>
    </inertial>
    <visual>
      <origin xyz="0. 0. 0." rpy="0. 0. 0."/>
      <geometry>
        <mesh filename="meshes/left_hand_thumb_rota_link1_visuals_mesh_0.obj" scale="1. 1. 1."/>
      </geometry>
    </visual>
    <visual>
      <origin xyz="0. 0. 0." rpy="0. 0. 0."/>
      <geometry>
        <mesh filename="meshes/left_hand_thumb_rota_link1_collisions_mesh_0.obj" scale="1. 1. 1."/>
      </geometry>
    </visual>
    <collision>
      <origin xyz="0. 0. 0." rpy="0. 0. 0."/>
      <geometry>
        <mesh filename="meshes/left_hand_thumb_rota_link1_collisions_mesh_0.obj" scale="1. 1. 1."/>
      </geometry>
    </collision>
  </link>
  <link name="left_hand_thumb_rota_link2">
    <inertial>
      <origin xyz="0. 0. 0." rpy="0. 0. 0."/>
      <mass value="0.0374006"/>
      <inertia ixx="0." ixy="0." ixz="0." iyy="0." iyz="0." izz="0."/>
    </inertial>
    <visual>
      <origin xyz="0. 0. 0." rpy="0. 0. 0."/>
      <geometry>
        <mesh filename="meshes/left_hand_thumb_rota_link2_visuals_mesh_0.obj" scale="1. 1. 1."/>
      </geometry>
    </visual>
    <visual>
      <origin xyz="0.0504025 0. 0. " rpy="0. 0. 0."/>
      <geometry>
        <mesh filename="meshes/left_hand_thumb_rota_link2_visuals_mesh_1.obj" scale="1. 1. 1."/>
      </geometry>
    </visual>
    <visual>
      <origin xyz="0. 0. 0." rpy="0. 0. 0."/>
      <geometry>
        <mesh filename="meshes/left_hand_thumb_rota_link2_collisions_mesh_0.obj" scale="1. 1. 1."/>
      </geometry>
    </visual>
    <visual>
      <origin xyz="0.0504025 0. 0. " rpy="0. 0. 0."/>
      <geometry>
        <mesh filename="meshes/left_hand_thumb_rota_link2_collisions_mesh_1.obj" scale="1. 1. 1."/>
      </geometry>
    </visual>
    <collision>
      <origin xyz="0. 0. 0." rpy="0. 0. 0."/>
      <geometry>
        <mesh filename="meshes/left_hand_thumb_rota_link2_collisions_mesh_0.obj" scale="1. 1. 1."/>
      </geometry>
    </collision>
    <collision>
      <origin xyz="0.0504025 0. 0. " rpy="0. 0. 0."/>
      <geometry>
        <mesh filename="meshes/left_hand_thumb_rota_link2_collisions_mesh_1.obj" scale="1. 1. 1."/>
      </geometry>
    </collision>
  </link>
  <link name="realman_xhand_left_rm_75_6f_description_rm_75_6f_description_base_link">
    <inertial>
      <origin xyz="0. 0. 0." rpy="0. 0. 0."/>
      <mass value="0.84105"/>
      <inertia ixx="0." ixy="0." ixz="0." iyy="0." iyz="0." izz="0."/>
    </inertial>
    <visual>
      <origin xyz="0. 0. 0." rpy="0. 0. 0."/>
      <geometry>
        <mesh filename="meshes/realman_xhand_left_rm_75_6f_description_rm_75_6f_description_base_link_visuals.obj" scale="1. 1. 1."/>
      </geometry>
    </visual>
    <visual>
      <origin xyz="0. 0. 0." rpy="0. 0. 0."/>
      <geometry>
        <mesh filename="meshes/realman_xhand_left_rm_75_6f_description_rm_75_6f_description_base_link_collisions.obj" scale="1. 1. 1."/>
      </geometry>
    </visual>
    <collision>
      <origin xyz="0. 0. 0." rpy="0. 0. 0."/>
      <geometry>
        <mesh filename="meshes/realman_xhand_left_rm_75_6f_description_rm_75_6f_description_base_link_collisions.obj" scale="1. 1. 1."/>
      </geometry>
    </collision>
  </link>
  <link name="xhand_left_base_link">
    <inertial>
      <origin xyz="0. 0. 0." rpy="0. 0. 0."/>
      <mass value="0.5299444"/>
      <inertia ixx="0." ixy="0." ixz="0." iyy="0." iyz="0." izz="0."/>
    </inertial>
    <visual>
      <origin xyz="0. 0. 0." rpy="0. 0. 0."/>
      <geometry>
        <mesh filename="meshes/xhand_left_base_link_visuals_mesh_0.obj" scale="1. 1. 1."/>
      </geometry>
    </visual>
    <visual>
      <origin xyz="0. 0. -0.065" rpy="0. 0. 0."/>
      <geometry>
        <mesh filename="meshes/xhand_left_base_link_visuals_mesh_1.obj" scale="1. 1. 1."/>
      </geometry>
    </visual>
    <visual>
      <origin xyz="0. 0. 0." rpy="0. 0. 0."/>
      <geometry>
        <mesh filename="meshes/xhand_left_base_link_collisions_mesh_0.obj" scale="1. 1. 1."/>
      </geometry>
    </visual>
    <visual>
      <origin xyz="0. 0. -0.065" rpy="0. 0. 0."/>
      <geometry>
        <mesh filename="meshes/xhand_left_base_link_collisions_mesh_1.obj" scale="1. 1. 1."/>
      </geometry>
    </visual>
    <collision>
      <origin xyz="0. 0. 0." rpy="0. 0. 0."/>
      <geometry>
        <mesh filename="meshes/xhand_left_base_link_collisions_mesh_0.obj" scale="1. 1. 1."/>
      </geometry>
    </collision>
    <collision>
      <origin xyz="0. 0. -0.065" rpy="0. 0. 0."/>
      <geometry>
        <mesh filename="meshes/xhand_left_base_link_collisions_mesh_1.obj" scale="1. 1. 1."/>
      </geometry>
    </collision>
  </link>
</robot>
